Workbook

Sheet verfvoorraad
B7: Kleurnaam: | C7: Artikelnummer: | D7: Reeks: | E7: Volledig nummer: | F7: In voorraad: | G7: Aantal: | H7: Bestellen: | I7: Aantal bestellen: | J7: Gewenst aantal
B8: Model Air - White | C8: 001 | D8: Model Air | E8: =IF(D8="Model Air","71."&C8,IF(D8="Model Color","70."&C8,IF(D8="Metal Color","77."&C8,IF(D8="Primer 200ml","74."&C8,IF(D8="Primer 60ml","73."&C8,IF(D8="Primer 17ml","70."&C8,IF(D8="Enamel Revell","REV-"&VALUE(C8),""))))))) -> 71.001 | F8: =IF(G8="","",IF(G8>0,"Ja","Nee")) -> Ja | G8: 4 | H8: Nee | I8: =IF(H8="Ja",IF(J8="",1,J8),"")
B9: Model Air - Yellow | C9: 002 | D9: Model Air | E9: =IF(D9="Model Air","71."&C9,IF(D9="Model Color","70."&C9,IF(D9="Metal Color","77."&C9,IF(D9="Primer 200ml","74."&C9,IF(D9="Primer 60ml","73."&C9,IF(D9="Primer 17ml","70."&C9,IF(D9="Enamel Revell","REV-"&VALUE(C9),""))))))) -> 71.002 | F9: =IF(G9="","",IF(G9>0,"Ja","Nee")) -> Ja | G9: 1 | H9: Nee | I9: =IF(H9="Ja",IF(J9="",1,J9),"")
B10: Model Air - Scarlet Red | C10: 003 | D10: Model Air | E10: =IF(D10="Model Air","71."&C10,IF(D10="Model Color","70."&C10,IF(D10="Metal Color","77."&C10,IF(D10="Primer 200ml","74."&C10,IF(D10="Primer 60ml","73."&C10,IF(D10="Primer 17ml","70."&C10,IF(D10="Enamel Revell","REV-"&VALUE(C10),""))))))) -> 71.003 | F10: =IF(G10="","",IF(G10>0,"Ja","Nee")) -> Ja | G10: 2 | H10: Nee | I10: =IF(H10="Ja",IF(J10="",1,J10),"")
B11: Model Air - Blue | C11: 004 | D11: Model Air | E11: =IF(D11="Model Air","71."&C11,IF(D11="Model Color","70."&C11,IF(D11="Metal Color","77."&C11,IF(D11="Primer 200ml","74."&C11,IF(D11="Primer 60ml","73."&C11,IF(D11="Primer 17ml","70."&C11,IF(D11="Enamel Revell","REV-"&VALUE(C11),""))))))) -> 71.004 | F11: =IF(G11="","",IF(G11>0,"Ja","Nee")) -> Ja | G11: 3 | H11: Nee | I11: =IF(H11="Ja",IF(J11="",1,J11),"")
B12: Model Air - Intermediate Blue | C12: 005 | D12: Model Air | E12: =IF(D12="Model Air","71."&C12,IF(D12="Model Color","70."&C12,IF(D12="Metal Color","77."&C12,IF(D12="Primer 200ml","74."&C12,IF(D12="Primer 60ml","73."&C12,IF(D12="Primer 17ml","70."&C12,IF(D12="Enamel Revell","REV-"&VALUE(C12),""))))))) -> 71.005 | F12: =IF(G12="","",IF(G12>0,"Ja","Nee")) -> Nee | G12: 0 | H12: Nee | I12: =IF(H12="Ja",IF(J12="",1,J12),"")
B13: Model Air - Camouflage Light Green | C13: 006 | D13: Model Air | E13: =IF(D13="Model Air","71."&C13,IF(D13="Model Color","70."&C13,IF(D13="Metal Color","77."&C13,IF(D13="Primer 200ml","74."&C13,IF(D13="Primer 60ml","73."&C13,IF(D13="Primer 17ml","70."&C13,IF(D13="Enamel Revell","REV-"&VALUE(C13),""))))))) -> 71.006 | F13: =IF(G13="","",IF(G13>0,"Ja","Nee")) -> Ja | G13: 1 | H13: Nee | I13: =IF(H13="Ja",IF(J13="",1,J13),"")
B14: Model Air - Olive Green | C14: 007 | D14: Model Air | E14: =IF(D14="Model Air","71."&C14,IF(D14="Model Color","70."&C14,IF(D14="Metal Color","77."&C14,IF(D14="Primer 200ml","74."&C14,IF(D14="Primer 60ml","73."&C14,IF(D14="Primer 17ml","70."&C14,IF(D14="Enamel Revell","REV-"&VALUE(C14),""))))))) -> 71.007 | F14: =IF(G14="","",IF(G14>0,"Ja","Nee")) -> Ja | G14: 3 | H14: Nee | I14: =IF(H14="Ja",IF(J14="",1,J14),"")
B15: Model Air - Pale Blue | C15: 008 | D15: Model Air | E15: =IF(D15="Model Air","71."&C15,IF(D15="Model Color","70."&C15,IF(D15="Metal Color","77."&C15,IF(D15="Primer 200ml","74."&C15,IF(D15="Primer 60ml","73."&C15,IF(D15="Primer 17ml","70."&C15,IF(D15="Enamel Revell","REV-"&VALUE(C15),""))))))) -> 71.008 | F15: =IF(G15="","",IF(G15>0,"Ja","Nee")) -> Nee | G15: 0 | H15: Nee | I15: =IF(H15="Ja",IF(J15="",1,J15),"")
B16: Model Air - Duck Egg Green | C16: 009 | D16: Model Air | E16: =IF(D16="Model Air","71."&C16,IF(D16="Model Color","70."&C16,IF(D16="Metal Color","77."&C16,IF(D16="Primer 200ml","74."&C16,IF(D16="Primer 60ml","73."&C16,IF(D16="Primer 17ml","70."&C16,IF(D16="Enamel Revell","REV-"&VALUE(C16),""))))))) -> 71.009 | F16: =IF(G16="","",IF(G16>0,"Ja","Nee")) -> Nee | G16: 0 | H16: Nee | I16: =IF(H16="Ja",IF(J16="",1,J16),"")
B17: Model Air - Interior Green | C17: 010 | D17: Model Air | E17: =IF(D17="Model Air","71."&C17,IF(D17="Model Color","70."&C17,IF(D17="Metal Color","77."&C17,IF(D17="Primer 200ml","74."&C17,IF(D17="Primer 60ml","73."&C17,IF(D17="Primer 17ml","70."&C17,IF(D17="Enamel Revell","REV-"&VALUE(C17),""))))))) -> 71.010 | F17: =IF(G17="","",IF(G17>0,"Ja","Nee")) -> Nee | G17: 0 | H17: Nee | I17: =IF(H17="Ja",IF(J17="",1,J17),"")
B18: Model Air - Tank Green | C18: 011 | D18: Model Air | E18: =IF(D18="Model Air","71."&C18,IF(D18="Model Color","70."&C18,IF(D18="Metal Color","77."&C18,IF(D18="Primer 200ml","74."&C18,IF(D18="Primer 60ml","73."&C18,IF(D18="Primer 17ml","70."&C18,IF(D18="Enamel Revell","REV-"&VALUE(C18),""))))))) -> 71.011 | F18: =IF(G18="","",IF(G18>0,"Ja","Nee")) -> Ja | G18: 1 | H18: Nee | I18: =IF(H18="Ja",IF(J18="",1,J18),"")
B19: Model Air - Dark Green | C19: 012 | D19: Model Air | E19: =IF(D19="Model Air","71."&C19,IF(D19="Model Color","70."&C19,IF(D19="Metal Color","77."&C19,IF(D19="Primer 200ml","74."&C19,IF(D19="Primer 60ml","73."&C19,IF(D19="Primer 17ml","70."&C19,IF(D19="Enamel Revell","REV-"&VALUE(C19),""))))))) -> 71.012 | F19: =IF(G19="","",IF(G19>0,"Ja","Nee")) -> Nee | G19: 0 | H19: Nee | I19: =IF(H19="Ja",IF(J19="",1,J19),"")
... B119: Model Air - Tire Black | C119: 315 | D119: Model Air | E119: =IF(D119="Model Air","71."&C119,IF(D119="Model Color","70."&C119,IF(D119="Metal Color","77."&C119,IF(D119="Primer 200ml","74."&C119,IF(D119="Primer 60ml","73."&C119,IF(D119="Primer 17ml","70."&C119,IF(D119="Enamel Revell","REV-"&VALUE(C119),""))))))) -> 71.315 | F119: =IF(G119="","",IF(G119>0,"Ja","Nee")) -> Ja | G119: 1 | H119: Nee | I119: =IF(H119="Ja",IF(J119="",1,J119),"")
B120: Model Color - Plastic Putty | C120: 400 | D120: Model Color | E120: =IF(D120="Model Air","71."&C120,IF(D120="Model Color","70."&C120,IF(D120="Metal Color","77."&C120,IF(D120="Primer 200ml","74."&C120,IF(D120="Primer 60ml","73."&C120,IF(D120="Primer 17ml","70."&C120,IF(D120="Enamel Revell","REV-"&VALUE(C120),""))))))) -> 70.400 | F120: =IF(G120="","",IF(G120>0,"Ja","Nee")) -> Nee | G120: 0 | H120: Nee | I120: =IF(H120="Ja",IF(J120="",1,J120),"")
B121: Model Color - Glossy Medium | C121: 470 | D121: Model Color | E121: =IF(D121="Model Air","71."&C121,IF(D121="Model Color","70."&C121,IF(D121="Metal Color","77."&C121,IF(D121="Primer 200ml","74."&C121,IF(D121="Primer 60ml","73."&C121,IF(D121="Primer 17ml","70."&C121,IF(D121="Enamel Revell","REV-"&VALUE(C121),""))))))) -> 70.470 | F121: =IF(G121="","",IF(G121>0,"Ja","Nee")) -> Nee | G121: 0 | H121: Nee | I121: =IF(H121="Ja",IF(J121="",1,J121),"")
B122: Model Color - Glossy Varnish | C122: 510 | D122: Model Color | E122: =IF(D122="Model Air","71."&C122,IF(D122="Model Color","70."&C122,IF(D122="Metal Color","77."&C122,IF(D122="Primer 200ml","74."&C122,IF(D122="Primer 60ml","73."&C122,IF(D122="Primer 17ml","70."&C122,IF(D122="Enamel Revell","REV-"&VALUE(C122),""))))))) -> 70.510 | F122: =IF(G122="","",IF(G122>0,"Ja","Nee")) -> Ja | G122: 1 | H122: Nee | I122: =IF(H122="Ja",IF(J122="",1,J122),"")
B123: Model Color - Matt Varnish | C123: 520 | D123: Model Color | E123: =IF(D123="Model Air","71."&C123,IF(D123="Model Color","70."&C123,IF(D123="Metal Color","77."&C123,IF(D123="Primer 200ml","74."&C123,IF(D123="Primer 60ml","73."&C123,IF(D123="Primer 17ml","70."&C123,IF(D123="Enamel Revell","REV-"&VALUE(C123),""))))))) -> 70.520 | F123: =IF(G123="","",IF(G123>0,"Ja","Nee")) -> Ja | G123: 1 | H123: Nee | I123: =IF(H123="Ja",IF(J123="",1,J123),"")
B124: Model Color - Metal Medium | C124: 521 | D124: Model Color | E124: =IF(D124="Model Air","71."&C124,IF(D124="Model Color","70."&C124,IF(D124="Metal Color","77."&C124,IF(D124="Primer 200ml","74."&C124,IF(D124="Primer 60ml","73."&C124,IF(D124="Primer 17ml","70."&C124,IF(D124="Enamel Revell","REV-"&VALUE(C124),""))))))) -> 70.521 | F124: =IF(G124="","",IF(G124>0,"Ja","Nee")) -> Nee | G124: 0 | H124: Nee | I124: =IF(H124="Ja",IF(J124="",1,J124),"")
B125: Model Color - Satin Varnish | C125: 522 | D125: Model Color | E125: =IF(D125="Model Air","71."&C125,IF(D125="Model Color","70."&C125,IF(D125="Metal Color","77."&C125,IF(D125="Primer 200ml","74."&C125,IF(D125="Primer 60ml","73."&C125,IF(D125="Primer 17ml","70."&C125,IF(D125="Enamel Revell","REV-"&VALUE(C125),""))))))) -> 70.522 | F125: =IF(G125="","",IF(G125>0,"Ja","Nee")) -> Ja | G125: 1 | H125: Nee | I125: =IF(H125="Ja",IF(J125="",1,J125),"")
B126: Model Color - Liquid Mask | C126: 523 | D126: Model Color | E126: =IF(D126="Model Air","71."&C126,IF(D126="Model Color","70."&C126,IF(D126="Metal Color","77."&C126,IF(D126="Primer 200ml","74."&C126,IF(D126="Primer 60ml","73."&C126,IF(D126="Primer 17ml","70."&C126,IF(D126="Enamel Revell","REV-"&VALUE(C126),""))))))) -> 70.523 | F126: =IF(G126="","",IF(G126>0,"Ja","Nee")) -> Nee | G126: 0 | H126: Nee | I126: =IF(H126="Ja",IF(J126="",1,J126),"")
B127: Model Color - Thinner | C127: 524 | D127: Model Color | E127: =IF(D127="Model Air","71."&C127,IF(D127="Model Color","70."&C127,IF(D127="Metal Color","77."&C127,IF(D127="Primer 200ml","74."&C127,IF(D127="Primer 60ml","73."&C127,IF(D127="Primer 17ml","70."&C127,IF(D127="Enamel Revell","REV-"&VALUE(C127),""))))))) -> 70.524 | F127: =IF(G127="","",IF(G127>0,"Ja","Nee")) -> Nee | G127: 0 | H127: Nee | I127: =IF(H127="Ja",IF(J127="",1,J127),"")
B128: Model Color - Matte Medium | C128: 540 | D128: Model Color | E128: =IF(D128="Model Air","71."&C128,IF(D128="Model Color","70."&C128,IF(D128="Metal Color","77."&C128,IF(D128="Primer 200ml","74."&C128,IF(D128="Primer 60ml","73."&C128,IF(D128="Primer 17ml","70."&C128,IF(D128="Enamel Revell","REV-"&VALUE(C128),""))))))) -> 70.540 | F128: =IF(G128="","",IF(G128>0,"Ja","Nee")) -> Nee | G128: 0 | H128: Nee | I128: =IF(H128="Ja",IF(J128="",1,J128),"")
B129: Model Color - Glaze Medium | C129: 596 | D129: Model Color | E129: =IF(D129="Model Air","71."&C129,IF(D129="Model Color","70."&C129,IF(D129="Metal Color","77."&C129,IF(D129="Primer 200ml","74."&C129,IF(D129="Primer 60ml","73."&C129,IF(D129="Primer 17ml","70."&C129,IF(D129="Enamel Revell","REV-"&VALUE(C129),""))))))) -> 70.596 | F129: =IF(G129="","",IF(G129>0,"Ja","Nee")) -> Nee | G129: 0 | H129: Nee | I129: =IF(H129="Ja",IF(J129="",1,J129),"")
B130: Model Color - Drying Retarder | C130: 597 | D130: Model Color | E130: =IF(D130="Model Air","71."&C130,IF(D130="Model Color","70."&C130,IF(D130="Metal Color","77."&C130,IF(D130="Primer 200ml","74."&C130,IF(D130="Primer 60ml","73."&C130,IF(D130="Primer 17ml","70."&C130,IF(D130="Enamel Revell","REV-"&VALUE(C130),""))))))) -> 70.597 | F130: =IF(G130="","",IF(G130>0,"Ja","Nee")) -> Nee | G130: 0 | H130: Nee | I130: =IF(H130="Ja",IF(J130="",1,J130),"")
B131: Model Color - Crackel Medium | C131: 598 | D131: Model Color | E131: =IF(D131="Model Air","71."&C131,IF(D131="Model Color","70."&C131,IF(D131="Metal Color","77."&C131,IF(D131="Primer 200ml","74."&C131,IF(D131="Primer 60ml","73."&C131,IF(D131="Primer 17ml","70."&C131,IF(D131="Enamel Revell","REV-"&VALUE(C131),""))))))) -> 70.598 | F131: =IF(G131="","",IF(G131>0,"Ja","Nee")) -> Nee | G131: 0 | H131: Nee | I131: =IF(H131="Ja",IF(J131="",1,J131),"")
... B433: Clear Blue | C433: 752 | D433: Enamel Revell | E433: =IF(D433="Model Air","71."&C433,IF(D433="Model Color","70."&C433,IF(D433="Metal Color","77."&C433,IF(D433="Primer 200ml","74."&C433,IF(D433="Primer 60ml","73."&C433,IF(D433="Primer 17ml","70."&C433,IF(D433="Enamel Revell","REV-"&VALUE(C433),""))))))) -> REV-752 | F433: =IF(G433="","",IF(G433>0,"Ja","Nee")) -> Nee | G433: 0 | H433: Nee | I433: =IF(H433="Ja",IF(J433="",1,J433),"")

Sheet Verf zoeken
B3: Verf zoeken
B5: Artikelnummer:
B7: Kleurnaam: | C7: =IF(C5="","",IF(LEFT(UPPER(C5),4)="REV-",_xlfn.XLOOKUP(UPPER(C5),verfvoorraad!E:E,verfvoorraad!B:B,"Niet gevonden"),IF(LEN(SUBSTITUTE(C5,".",""))=3,_xlfn.XLOOKUP(C5,verfvoorraad!C:C,verfvoorraad!B:B,"Niet gevonden"),_xlfn.XLOOKUP(IF(ISNUMBER(SEARCH(".",C5)),C5,LEFT(C5,2)&"."&RIGHT(C5,3)),verfvoorraad!E:E,verfvoorraad!B:B,"Niet gevonden"))))
B8: Reeks: | C8: =IF(C5="","",IF(LEFT(UPPER(C5),4)="REV-",_xlfn.XLOOKUP(UPPER(C5),verfvoorraad!E:E,verfvoorraad!D:D,"Niet gevonden"),IF(LEN(SUBSTITUTE(C5,".",""))=3,_xlfn.XLOOKUP(C5,verfvoorraad!C:C,verfvoorraad!D:D,"Niet gevonden"),_xlfn.XLOOKUP(IF(ISNUMBER(SEARCH(".",C5)),C5,LEFT(C5,2)&"."&RIGHT(C5,3)),verfvoorraad!E:E,verfvoorraad!D:D,"Niet gevonden"))))
B9: In voorraad: | C9: =IF(C5="","",IF(LEFT(UPPER(C5),4)="REV-",_xlfn.XLOOKUP(UPPER(C5),verfvoorraad!E:E,verfvoorraad!F:F,"Niet gevonden"),IF(LEN(SUBSTITUTE(C5,".",""))=3,_xlfn.XLOOKUP(C5,verfvoorraad!C:C,verfvoorraad!F:F,"Niet gevonden"),_xlfn.XLOOKUP(IF(ISNUMBER(SEARCH(".",C5)),C5,LEFT(C5,2)&"."&RIGHT(C5,3)),verfvoorraad!E:E,verfvoorraad!F:F,"Niet gevonden"))))
B10: Aantal: | C10: =IF(C5="","",IF(LEFT(UPPER(C5),4)="REV-",_xlfn.XLOOKUP(UPPER(C5),verfvoorraad!E:E,verfvoorraad!G:G,"Niet gevonden"),IF(LEN(SUBSTITUTE(C5,".",""))=3,_xlfn.XLOOKUP(C5,verfvoorraad!C:C,verfvoorraad!G:G,"Niet gevonden"),_xlfn.XLOOKUP(IF(ISNUMBER(SEARCH(".",C5)),C5,LEFT(C5,2)&"."&RIGHT(C5,3)),verfvoorraad!E:E,verfvoorraad!G:G,"Niet gevonden"))))
B11: Bestellen: | C11: =IF(C5="","",IF(LEFT(UPPER(C5),4)="REV-",_xlfn.XLOOKUP(UPPER(C5),verfvoorraad!E:E,verfvoorraad!H:H,"Niet gevonden"),IF(LEN(SUBSTITUTE(C5,".",""))=3,_xlfn.XLOOKUP(C5,verfvoorraad!C:C,verfvoorraad!H:H,"Niet gevonden"),_xlfn.XLOOKUP(IF(ISNUMBER(SEARCH(".",C5)),C5,LEFT(C5,2)&"."&RIGHT(C5,3)),verfvoorraad!E:E,verfvoorraad!H:H,"Niet gevonden"))))
B12: Volledig nummer: | C12: =IF(C5="","",IF(LEFT(UPPER(C5),4)="REV-",_xlfn.XLOOKUP(UPPER(C5),verfvoorraad!E:E,verfvoorraad!E:E,"Niet gevonden"),IF(LEN(SUBSTITUTE(C5,".",""))=3,_xlfn.XLOOKUP(C5,verfvoorraad!C:C,verfvoorraad!E:E,"Niet gevonden"),_xlfn.XLOOKUP(IF(ISNUMBER(SEARCH(".",C5)),C5,LEFT(C5,2)&"."&RIGHT(C5,3)),verfvoorraad!E:E,verfvoorraad!E:E,"Niet gevonden"))))
B15: zoeken op kleurnaam | K15: Meerdere kleuren controleren
B17: kleurnaam: | C17: yellow
B19: Kleurnaam | C19: Artikelnummer | D19: Reeks | E19: Volledig nummer | F19: In voorraad | G19: Aantal | H19: Bestellen | K19: Ingegeven nummer: | L19: Kleurnaam: | M19: Reeks: | N19: Volledig nummer: | O19: In voorraad: | P19: Aantal: | Q19: Bestellen: | R19: Naar bestellijst:
B20: {=IF(C17="","",_xlfn._xlws.SORT(_xlfn._xlws.FILTER(verfvoorraad!B8:H505,ISNUMBER(IFERROR(SEARCH(C17,verfvoorraad!B8:B505),"")),"Geen resultaten"),6,-1))} -> Model Air - Sand Yellow | C20: 028 | D20: Model Air | E20: 71.028 | F20: Ja | G20: 2 | H20: Nee | L20: =IF(K20="","",IFERROR(_xlfn.XLOOKUP(K20,verfvoorraad!C:C,verfvoorraad!B:B),IFERROR(_xlfn.XLOOKUP(IF(LEFT(UPPER(K20),4)="REV-","REV-"&VALUE(MID(K20,5,99)),IF(LEN(K20)=5,LEFT(K20,2)&"."&RIGHT(K20,3),K20)),verfvoorraad!E:E,verfvoorraad!B:B),"Niet gevonden"))) | M20: =IF(K20="","",IFERROR(_xlfn.XLOOKUP(K20,verfvoorraad!C:C,verfvoorraad!D:D),IFERROR(_xlfn.XLOOKUP(IF(LEFT(UPPER(K20),4)="REV-","REV-"&VALUE(MID(K20,5,99)),IF(LEN(K20)=5,LEFT(K20,2)&"."&RIGHT(K20,3),K20)),verfvoorraad!E:E,verfvoorraad!D:D),"Niet gevonden"))) | N20: =IF(K20="","",IFERROR(_xlfn.XLOOKUP(K20,verfvoorraad!C:C,verfvoorraad!E:E),IFERROR(_xlfn.XLOOKUP(IF(LEFT(UPPER(K20),4)="REV-","REV-"&VALUE(MID(K20,5,99)),IF(LEN(K20)=5,LEFT(K20,2)&"."&RIGHT(K20,3),K20)),verfvoorraad!E:E,verfvoorraad!E:E),"Niet gevonden"))) | O20: =IF(K20="","",IFERROR(_xlfn.XLOOKUP(K20,verfvoorraad!C:C,verfvoorraad!F:F),IFERROR(_xlfn.XLOOKUP(IF(LEFT(UPPER(K20),4)="REV-","REV-"&VALUE(MID(K20,5,99)),IF(LEN(K20)=5,LEFT(K20,2)&"."&RIGHT(K20,3),K20)),verfvoorraad!E:E,verfvoorraad!F:F),"Niet gevonden"))) | P20: =IF(K20="","",IFERROR(_xlfn.XLOOKUP(K20,verfvoorraad!C:C,verfvoorraad!G:G),IFERROR(_xlfn.XLOOKUP(IF(LEFT(UPPER(K20),4)="REV-","REV-"&VALUE(MID(K20,5,99)),IF(LEN(K20)=5,LEFT(K20,2)&"."&RIGHT(K20,3),K20)),verfvoorraad!E:E,verfvoorraad!G:G),"Niet gevonden"))) | Q20: =IF(K20="","",IF(O20="Ja","Nee",IF(O20="Nee","Ja",IF(O20="Niet gevonden","Niet gevonden","")))) | R20: =IF(Q20="Ja","Toevoegen","")
B21: Gloss Yellow | C21: 12 | D21: Enamel Revell | E21: REV-12 | F21: Ja | G21: 2 | H21: Nee | L21: =IF(K21="","",IFERROR(_xlfn.XLOOKUP(K21,verfvoorraad!C:C,verfvoorraad!B:B),IFERROR(_xlfn.XLOOKUP(IF(LEFT(UPPER(K21),4)="REV-","REV-"&VALUE(MID(K21,5,99)),IF(LEN(K21)=5,LEFT(K21,2)&"."&RIGHT(K21,3),K21)),verfvoorraad!E:E,verfvoorraad!B:B),"Niet gevonden"))) | M21: =IF(K21="","",IFERROR(_xlfn.XLOOKUP(K21,verfvoorraad!C:C,verfvoorraad!D:D),IFERROR(_xlfn.XLOOKUP(IF(LEFT(UPPER(K21),4)="REV-","REV-"&VALUE(MID(K21,5,99)),IF(LEN(K21)=5,LEFT(K21,2)&"."&RIGHT(K21,3),K21)),verfvoorraad!E:E,verfvoorraad!D:D),"Niet gevonden"))) | N21: =IF(K21="","",IFERROR(_xlfn.XLOOKUP(K21,verfvoorraad!C:C,verfvoorraad!E:E),IFERROR(_xlfn.XLOOKUP(IF(LEFT(UPPER(K21),4)="REV-","REV-"&VALUE(MID(K21,5,99)),IF(LEN(K21)=5,LEFT(K21,2)&"."&RIGHT(K21,3),K21)),verfvoorraad!E:E,verfvoorraad!E:E),"Niet gevonden"))) | O21: =IF(K21="","",IFERROR(_xlfn.XLOOKUP(K21,verfvoorraad!C:C,verfvoorraad!F:F),IFERROR(_xlfn.XLOOKUP(IF(LEFT(UPPER(K21),4)="REV-","REV-"&VALUE(MID(K21,5,99)),IF(LEN(K21)=5,LEFT(K21,2)&"."&RIGHT(K21,3),K21)),verfvoorraad!E:E,verfvoorraad!F:F),"Niet gevonden"))) | P21: =IF(K21="","",IFERROR(_xlfn.XLOOKUP(K21,verfvoorraad!C:C,verfvoorraad!G:G),IFERROR(_xlfn.XLOOKUP(IF(LEFT(UPPER(K21),4)="REV-","REV-"&VALUE(MID(K21,5,99)),IF(LEN(K21)=5,LEFT(K21,2)&"."&RIGHT(K21,3),K21)),verfvoorraad!E:E,verfvoorraad!G:G),"Niet gevonden"))) | Q21: =IF(K21="","",IF(O21="Ja","Nee",IF(O21="Nee","Ja",IF(O21="Niet gevonden","Niet gevonden","")))) | R21: =IF(Q21="Ja","Toevoegen","")
B22: Model Air - Yellow | C22: 002 | D22: Model Air | E22: 71.002 | F22: Ja | G22: 1 | H22: Nee | L22: =IF(K22="","",IFERROR(_xlfn.XLOOKUP(K22,verfvoorraad!C:C,verfvoorraad!B:B),IFERROR(_xlfn.XLOOKUP(IF(LEFT(UPPER(K22),4)="REV-","REV-"&VALUE(MID(K22,5,99)),IF(LEN(K22)=5,LEFT(K22,2)&"."&RIGHT(K22,3),K22)),verfvoorraad!E:E,verfvoorraad!B:B),"Niet gevonden"))) | M22: =IF(K22="","",IFERROR(_xlfn.XLOOKUP(K22,verfvoorraad!C:C,verfvoorraad!D:D),IFERROR(_xlfn.XLOOKUP(IF(LEFT(UPPER(K22),4)="REV-","REV-"&VALUE(MID(K22,5,99)),IF(LEN(K22)=5,LEFT(K22,2)&"."&RIGHT(K22,3),K22)),verfvoorraad!E:E,verfvoorraad!D:D),"Niet gevonden"))) | N22: =IF(K22="","",IFERROR(_xlfn.XLOOKUP(K22,verfvoorraad!C:C,verfvoorraad!E:E),IFERROR(_xlfn.XLOOKUP(IF(LEFT(UPPER(K22),4)="REV-","REV-"&VALUE(MID(K22,5,99)),IF(LEN(K22)=5,LEFT(K22,2)&"."&RIGHT(K22,3),K22)),verfvoorraad!E:E,verfvoorraad!E:E),"Niet gevonden"))) | O22: =IF(K22="","",IFERROR(_xlfn.XLOOKUP(K22,verfvoorraad!C:C,verfvoorraad!F:F),IFERROR(_xlfn.XLOOKUP(IF(LEFT(UPPER(K22),4)="REV-","REV-"&VALUE(MID(K22,5,99)),IF(LEN(K22)=5,LEFT(K22,2)&"."&RIGHT(K22,3),K22)),verfvoorraad!E:E,verfvoorraad!F:F),"Niet gevonden"))) | P22: =IF(K22="","",IFERROR(_xlfn.XLOOKUP(K22,verfvoorraad!C:C,verfvoorraad!G:G),IFERROR(_xlfn.XLOOKUP(IF(LEFT(UPPER(K22),4)="REV-","REV-"&VALUE(MID(K22,5,99)),IF(LEN(K22)=5,LEFT(K22,2)&"."&RIGHT(K22,3),K22)),verfvoorraad!E:E,verfvoorraad!G:G),"Niet gevonden"))) | Q22: =IF(K22="","",IF(O22="Ja","Nee",IF(O22="Nee","Ja",IF(O22="Niet gevonden","Niet gevonden","")))) | R22: =IF(Q22="Ja","Toevoegen","")
B23: Model Air - Yellow Olive | C23: 013 | D23: Model Air | E23: 71.013 | F23: Ja | G23: 1 | H23: Nee | L23: =IF(K23="","",IFERROR(_xlfn.XLOOKUP(K23,verfvoorraad!C:C,verfvoorraad!B:B),IFERROR(_xlfn.XLOOKUP(IF(LEFT(UPPER(K23),4)="REV-","REV-"&VALUE(MID(K23,5,99)),IF(LEN(K23)=5,LEFT(K23,2)&"."&RIGHT(K23,3),K23)),verfvoorraad!E:E,verfvoorraad!B:B),"Niet gevonden"))) | M23: =IF(K23="","",IFERROR(_xlfn.XLOOKUP(K23,verfvoorraad!C:C,verfvoorraad!D:D),IFERROR(_xlfn.XLOOKUP(IF(LEFT(UPPER(K23),4)="REV-","REV-"&VALUE(MID(K23,5,99)),IF(LEN(K23)=5,LEFT(K23,2)&"."&RIGHT(K23,3),K23)),verfvoorraad!E:E,verfvoorraad!D:D),"Niet gevonden"))) | N23: =IF(K23="","",IFERROR(_xlfn.XLOOKUP(K23,verfvoorraad!C:C,verfvoorraad!E:E),IFERROR(_xlfn.XLOOKUP(IF(LEFT(UPPER(K23),4)="REV-","REV-"&VALUE(MID(K23,5,99)),IF(LEN(K23)=5,LEFT(K23,2)&"."&RIGHT(K23,3),K23)),verfvoorraad!E:E,verfvoorraad!E:E),"Niet gevonden"))) | O23: =IF(K23="","",IFERROR(_xlfn.XLOOKUP(K23,verfvoorraad!C:C,verfvoorraad!F:F),IFERROR(_xlfn.XLOOKUP(IF(LEFT(UPPER(K23),4)="REV-","REV-"&VALUE(MID(K23,5,99)),IF(LEN(K23)=5,LEFT(K23,2)&"."&RIGHT(K23,3),K23)),verfvoorraad!E:E,verfvoorraad!F:F),"Niet gevonden"))) | P23: =IF(K23="","",IFERROR(_xlfn.XLOOKUP(K23,verfvoorraad!C:C,verfvoorraad!G:G),IFERROR(_xlfn.XLOOKUP(IF(LEFT(UPPER(K23),4)="REV-","REV-"&VALUE(MID(K23,5,99)),IF(LEN(K23)=5,LEFT(K23,2)&"."&RIGHT(K23,3),K23)),verfvoorraad!E:E,verfvoorraad!G:G),"Niet gevonden"))) | Q23: =IF(K23="","",IF(O23="Ja","Nee",IF(O23="Nee","Ja",IF(O23="Niet gevonden","Niet gevonden","")))) | R23: =IF(Q23="Ja","Toevoegen","")
B24: Model Air - Dark Yellow | C24: 025 | D24: Model Air | E24: 71.025 | F24: Ja | G24: 1 | H24: Nee | L24: =IF(K24="","",IFERROR(_xlfn.XLOOKUP(K24,verfvoorraad!C:C,verfvoorraad!B:B),IFERROR(_xlfn.XLOOKUP(IF(LEFT(UPPER(K24),4)="REV-","REV-"&VALUE(MID(K24,5,99)),IF(LEN(K24)=5,LEFT(K24,2)&"."&RIGHT(K24,3),K24)),verfvoorraad!E:E,verfvoorraad!B:B),"Niet gevonden"))) | M24: =IF(K24="","",IFERROR(_xlfn.XLOOKUP(K24,verfvoorraad!C:C,verfvoorraad!D:D),IFERROR(_xlfn.XLOOKUP(IF(LEFT(UPPER(K24),4)="REV-","REV-"&VALUE(MID(K24,5,99)),IF(LEN(K24)=5,LEFT(K24,2)&"."&RIGHT(K24,3),K24)),verfvoorraad!E:E,verfvoorraad!D:D),"Niet gevonden"))) | N24: =IF(K24="","",IFERROR(_xlfn.XLOOKUP(K24,verfvoorraad!C:C,verfvoorraad!E:E),IFERROR(_xlfn.XLOOKUP(IF(LEFT(UPPER(K24),4)="REV-","REV-"&VALUE(MID(K24,5,99)),IF(LEN(K24)=5,LEFT(K24,2)&"."&RIGHT(K24,3),K24)),verfvoorraad!E:E,verfvoorraad!E:E),"Niet gevonden"))) | O24: =IF(K24="","",IFERROR(_xlfn.XLOOKUP(K24,verfvoorraad!C:C,verfvoorraad!F:F),IFERROR(_xlfn.XLOOKUP(IF(LEFT(UPPER(K24),4)="REV-","REV-"&VALUE(MID(K24,5,99)),IF(LEN(K24)=5,LEFT(K24,2)&"."&RIGHT(K24,3),K24)),verfvoorraad!E:E,verfvoorraad!F:F),"Niet gevonden"))) | P24: =IF(K24="","",IFERROR(_xlfn.XLOOKUP(K24,verfvoorraad!C:C,verfvoorraad!G:G),IFERROR(_xlfn.XLOOKUP(IF(LEFT(UPPER(K24),4)="REV-","REV-"&VALUE(MID(K24,5,99)),IF(LEN(K24)=5,LEFT(K24,2)&"."&RIGHT(K24,3),K24)),verfvoorraad!E:E,verfvoorraad!G:G),"Niet gevonden"))) | Q24: =IF(K24="","",IF(O24="Ja","Nee",IF(O24="Nee","Ja",IF(O24="Niet gevonden","Niet gevonden","")))) | R24: =IF(Q24="Ja","Toevoegen","")
B25: Model Air - Gold Yellow | C25: 078 | D25: Model Air | E25: 71.078 | F25: Ja | G25: 1 | H25: Nee | L25: =IF(K25="","",IFERROR(_xlfn.XLOOKUP(K25,verfvoorraad!C:C,verfvoorraad!B:B),IFERROR(_xlfn.XLOOKUP(IF(LEFT(UPPER(K25),4)="REV-","REV-"&VALUE(MID(K25,5,99)),IF(LEN(K25)=5,LEFT(K25,2)&"."&RIGHT(K25,3),K25)),verfvoorraad!E:E,verfvoorraad!B:B),"Niet gevonden"))) | M25: =IF(K25="","",IFERROR(_xlfn.XLOOKUP(K25,verfvoorraad!C:C,verfvoorraad!D:D),IFERROR(_xlfn.XLOOKUP(IF(LEFT(UPPER(K25),4)="REV-","REV-"&VALUE(MID(K25,5,99)),IF(LEN(K25)=5,LEFT(K25,2)&"."&RIGHT(K25,3),K25)),verfvoorraad!E:E,verfvoorraad!D:D),"Niet gevonden"))) | N25: =IF(K25="","",IFERROR(_xlfn.XLOOKUP(K25,verfvoorraad!C:C,verfvoorraad!E:E),IFERROR(_xlfn.XLOOKUP(IF(LEFT(UPPER(K25),4)="REV-","REV-"&VALUE(MID(K25,5,99)),IF(LEN(K25)=5,LEFT(K25,2)&"."&RIGHT(K25,3),K25)),verfvoorraad!E:E,verfvoorraad!E:E),"Niet gevonden"))) | O25: =IF(K25="","",IFERROR(_xlfn.XLOOKUP(K25,verfvoorraad!C:C,verfvoorraad!F:F),IFERROR(_xlfn.XLOOKUP(IF(LEFT(UPPER(K25),4)="REV-","REV-"&VALUE(MID(K25,5,99)),IF(LEN(K25)=5,LEFT(K25,2)&"."&RIGHT(K25,3),K25)),verfvoorraad!E:E,verfvoorraad!F:F),"Niet gevonden"))) | P25: =IF(K25="","",IFERROR(_xlfn.XLOOKUP(K25,verfvoorraad!C:C,verfvoorraad!G:G),IFERROR(_xlfn.XLOOKUP(IF(LEFT(UPPER(K25),4)="REV-","REV-"&VALUE(MID(K25,5,99)),IF(LEN(K25)=5,LEFT(K25,2)&"."&RIGHT(K25,3),K25)),verfvoorraad!E:E,verfvoorraad!G:G),"Niet gevonden"))) | Q25: =IF(K25="","",IF(O25="Ja","Nee",IF(O25="Nee","Ja",IF(O25="Niet gevonden","Niet gevonden","")))) | R25: =IF(Q25="Ja","Toevoegen","")
B26: Model Air - US Earth Yellow | C26: 291 | D26: Model Air | E26: 71.291 | F26: Ja | G26: 1 | H26: Nee | L26: =IF(K26="","",IFERROR(_xlfn.XLOOKUP(K26,verfvoorraad!C:C,verfvoorraad!B:B),IFERROR(_xlfn.XLOOKUP(IF(LEFT(UPPER(K26),4)="REV-","REV-"&VALUE(MID(K26,5,99)),IF(LEN(K26)=5,LEFT(K26,2)&"."&RIGHT(K26,3),K26)),verfvoorraad!E:E,verfvoorraad!B:B),"Niet gevonden"))) | M26: =IF(K26="","",IFERROR(_xlfn.XLOOKUP(K26,verfvoorraad!C:C,verfvoorraad!D:D),IFERROR(_xlfn.XLOOKUP(IF(LEFT(UPPER(K26),4)="REV-","REV-"&VALUE(MID(K26,5,99)),IF(LEN(K26)=5,LEFT(K26,2)&"."&RIGHT(K26,3),K26)),verfvoorraad!E:E,verfvoorraad!D:D),"Niet gevonden"))) | N26: =IF(K26="","",IFERROR(_xlfn.XLOOKUP(K26,verfvoorraad!C:C,verfvoorraad!E:E),IFERROR(_xlfn.XLOOKUP(IF(LEFT(UPPER(K26),4)="REV-","REV-"&VALUE(MID(K26,5,99)),IF(LEN(K26)=5,LEFT(K26,2)&"."&RIGHT(K26,3),K26)),verfvoorraad!E:E,verfvoorraad!E:E),"Niet gevonden"))) | O26: =IF(K26="","",IFERROR(_xlfn.XLOOKUP(K26,verfvoorraad!C:C,verfvoorraad!F:F),IFERROR(_xlfn.XLOOKUP(IF(LEFT(UPPER(K26),4)="REV-","REV-"&VALUE(MID(K26,5,99)),IF(LEN(K26)=5,LEFT(K26,2)&"."&RIGHT(K26,3),K26)),verfvoorraad!E:E,verfvoorraad!F:F),"Niet gevonden"))) | P26: =IF(K26="","",IFERROR(_xlfn.XLOOKUP(K26,verfvoorraad!C:C,verfvoorraad!G:G),IFERROR(_xlfn.XLOOKUP(IF(LEFT(UPPER(K26),4)="REV-","REV-"&VALUE(MID(K26,5,99)),IF(LEN(K26)=5,LEFT(K26,2)&"."&RIGHT(K26,3),K26)),verfvoorraad!E:E,verfvoorraad!G:G),"Niet gevonden"))) | Q26: =IF(K26="","",IF(O26="Ja","Nee",IF(O26="Nee","Ja",IF(O26="Niet gevonden","Niet gevonden","")))) | R26: =IF(Q26="Ja","Toevoegen","")
B27: Flat Yellow | C27: 15 | D27: Enamel Revell | E27: REV-15 | F27: Ja | G27: 1 | H27: Nee | L27: =IF(K27="","",IFERROR(_xlfn.XLOOKUP(K27,verfvoorraad!C:C,verfvoorraad!B:B),IFERROR(_xlfn.XLOOKUP(IF(LEFT(UPPER(K27),4)="REV-","REV-"&VALUE(MID(K27,5,99)),IF(LEN(K27)=5,LEFT(K27,2)&"."&RIGHT(K27,3),K27)),verfvoorraad!E:E,verfvoorraad!B:B),"Niet gevonden"))) | M27: =IF(K27="","",IFERROR(_xlfn.XLOOKUP(K27,verfvoorraad!C:C,verfvoorraad!D:D),IFERROR(_xlfn.XLOOKUP(IF(LEFT(UPPER(K27),4)="REV-","REV-"&VALUE(MID(K27,5,99)),IF(LEN(K27)=5,LEFT(K27,2)&"."&RIGHT(K27,3),K27)),verfvoorraad!E:E,verfvoorraad!D:D),"Niet gevonden"))) | N27: =IF(K27="","",IFERROR(_xlfn.XLOOKUP(K27,verfvoorraad!C:C,verfvoorraad!E:E),IFERROR(_xlfn.XLOOKUP(IF(LEFT(UPPER(K27),4)="REV-","REV-"&VALUE(MID(K27,5,99)),IF(LEN(K27)=5,LEFT(K27,2)&"."&RIGHT(K27,3),K27)),verfvoorraad!E:E,verfvoorraad!E:E),"Niet gevonden"))) | O27: =IF(K27="","",IFERROR(_xlfn.XLOOKUP(K27,verfvoorraad!C:C,verfvoorraad!F:F),IFERROR(_xlfn.XLOOKUP(IF(LEFT(UPPER(K27),4)="REV-","REV-"&VALUE(MID(K27,5,99)),IF(LEN(K27)=5,LEFT(K27,2)&"."&RIGHT(K27,3),K27)),verfvoorraad!E:E,verfvoorraad!F:F),"Niet gevonden"))) | P27: =IF(K27="","",IFERROR(_xlfn.XLOOKUP(K27,verfvoorraad!C:C,verfvoorraad!G:G),IFERROR(_xlfn.XLOOKUP(IF(LEFT(UPPER(K27),4)="REV-","REV-"&VALUE(MID(K27,5,99)),IF(LEN(K27)=5,LEFT(K27,2)&"."&RIGHT(K27,3),K27)),verfvoorraad!E:E,verfvoorraad!G:G),"Niet gevonden"))) | Q27: =IF(K27="","",IF(O27="Ja","Nee",IF(O27="Nee","Ja",IF(O27="Niet gevonden","Niet gevonden","")))) | R27: =IF(Q27="Ja","Toevoegen","")
B28: Flat Sandy Yellow | C28: 16 | D28: Enamel Revell | E28: REV-16 | F28: Ja | G28: 1 | H28: Nee | L28: =IF(K28="","",IFERROR(_xlfn.XLOOKUP(K28,verfvoorraad!C:C,verfvoorraad!B:B),IFERROR(_xlfn.XLOOKUP(IF(LEFT(UPPER(K28),4)="REV-","REV-"&VALUE(MID(K28,5,99)),IF(LEN(K28)=5,LEFT(K28,2)&"."&RIGHT(K28,3),K28)),verfvoorraad!E:E,verfvoorraad!B:B),"Niet gevonden"))) | M28: =IF(K28="","",IFERROR(_xlfn.XLOOKUP(K28,verfvoorraad!C:C,verfvoorraad!D:D),IFERROR(_xlfn.XLOOKUP(IF(LEFT(UPPER(K28),4)="REV-","REV-"&VALUE(MID(K28,5,99)),IF(LEN(K28)=5,LEFT(K28,2)&"."&RIGHT(K28,3),K28)),verfvoorraad!E:E,verfvoorraad!D:D),"Niet gevonden"))) | N28: =IF(K28="","",IFERROR(_xlfn.XLOOKUP(K28,verfvoorraad!C:C,verfvoorraad!E:E),IFERROR(_xlfn.XLOOKUP(IF(LEFT(UPPER(K28),4)="REV-","REV-"&VALUE(MID(K28,5,99)),IF(LEN(K28)=5,LEFT(K28,2)&"."&RIGHT(K28,3),K28)),verfvoorraad!E:E,verfvoorraad!E:E),"Niet gevonden"))) | O28: =IF(K28="","",IFERROR(_xlfn.XLOOKUP(K28,verfvoorraad!C:C,verfvoorraad!F:F),IFERROR(_xlfn.XLOOKUP(IF(LEFT(UPPER(K28),4)="REV-","REV-"&VALUE(MID(K28,5,99)),IF(LEN(K28)=5,LEFT(K28,2)&"."&RIGHT(K28,3),K28)),verfvoorraad!E:E,verfvoorraad!F:F),"Niet gevonden"))) | P28: =IF(K28="","",IFERROR(_xlfn.XLOOKUP(K28,verfvoorraad!C:C,verfvoorraad!G:G),IFERROR(_xlfn.XLOOKUP(IF(LEFT(UPPER(K28),4)="REV-","REV-"&VALUE(MID(K28,5,99)),IF(LEN(K28)=5,LEFT(K28,2)&"."&RIGHT(K28,3),K28)),verfvoorraad!E:E,verfvoorraad!G:G),"Niet gevonden"))) | Q28: =IF(K28="","",IF(O28="Ja","Nee",IF(O28="Nee","Ja",IF(O28="Niet gevonden","Niet gevonden","")))) | R28: =IF(Q28="Ja","Toevoegen","")
B29: Model Air - Tank Dark Yellow 1943 | C29: 081 | D29: Model Air | E29: 71.081 | F29: Nee | G29: 0 | H29: Nee | L29: =IF(K29="","",IFERROR(_xlfn.XLOOKUP(K29,verfvoorraad!C:C,verfvoorraad!B:B),IFERROR(_xlfn.XLOOKUP(IF(LEFT(UPPER(K29),4)="REV-","REV-"&VALUE(MID(K29,5,99)),IF(LEN(K29)=5,LEFT(K29,2)&"."&RIGHT(K29,3),K29)),verfvoorraad!E:E,verfvoorraad!B:B),"Niet gevonden"))) | M29: =IF(K29="","",IFERROR(_xlfn.XLOOKUP(K29,verfvoorraad!C:C,verfvoorraad!D:D),IFERROR(_xlfn.XLOOKUP(IF(LEFT(UPPER(K29),4)="REV-","REV-"&VALUE(MID(K29,5,99)),IF(LEN(K29)=5,LEFT(K29,2)&"."&RIGHT(K29,3),K29)),verfvoorraad!E:E,verfvoorraad!D:D),"Niet gevonden"))) | N29: =IF(K29="","",IFERROR(_xlfn.XLOOKUP(K29,verfvoorraad!C:C,verfvoorraad!E:E),IFERROR(_xlfn.XLOOKUP(IF(LEFT(UPPER(K29),4)="REV-","REV-"&VALUE(MID(K29,5,99)),IF(LEN(K29)=5,LEFT(K29,2)&"."&RIGHT(K29,3),K29)),verfvoorraad!E:E,verfvoorraad!E:E),"Niet gevonden"))) | O29: =IF(K29="","",IFERROR(_xlfn.XLOOKUP(K29,verfvoorraad!C:C,verfvoorraad!F:F),IFERROR(_xlfn.XLOOKUP(IF(LEFT(UPPER(K29),4)="REV-","REV-"&VALUE(MID(K29,5,99)),IF(LEN(K29)=5,LEFT(K29,2)&"."&RIGHT(K29,3),K29)),verfvoorraad!E:E,verfvoorraad!F:F),"Niet gevonden"))) | P29: =IF(K29="","",IFERROR(_xlfn.XLOOKUP(K29,verfvoorraad!C:C,verfvoorraad!G:G),IFERROR(_xlfn.XLOOKUP(IF(LEFT(UPPER(K29),4)="REV-","REV-"&VALUE(MID(K29,5,99)),IF(LEN(K29)=5,LEFT(K29,2)&"."&RIGHT(K29,3),K29)),verfvoorraad!E:E,verfvoorraad!G:G),"Niet gevonden"))) | Q29: =IF(K29="","",IF(O29="Ja","Nee",IF(O29="Nee","Ja",IF(O29="Niet gevonden","Niet gevonden","")))) | R29: =IF(Q29="Ja","Toevoegen","")
B30: Model Color - Fluorescent Yellow | C30: 730 | D30: Model Color | E30: 70.730 | F30: Nee | G30: 0 | H30: Nee | L30: =IF(K30="","",IFERROR(_xlfn.XLOOKUP(K30,verfvoorraad!C:C,verfvoorraad!B:B),IFERROR(_xlfn.XLOOKUP(IF(LEFT(UPPER(K30),4)="REV-","REV-"&VALUE(MID(K30,5,99)),IF(LEN(K30)=5,LEFT(K30,2)&"."&RIGHT(K30,3),K30)),verfvoorraad!E:E,verfvoorraad!B:B),"Niet gevonden"))) | M30: =IF(K30="","",IFERROR(_xlfn.XLOOKUP(K30,verfvoorraad!C:C,verfvoorraad!D:D),IFERROR(_xlfn.XLOOKUP(IF(LEFT(UPPER(K30),4)="REV-","REV-"&VALUE(MID(K30,5,99)),IF(LEN(K30)=5,LEFT(K30,2)&"."&RIGHT(K30,3),K30)),verfvoorraad!E:E,verfvoorraad!D:D),"Niet gevonden"))) | N30: =IF(K30="","",IFERROR(_xlfn.XLOOKUP(K30,verfvoorraad!C:C,verfvoorraad!E:E),IFERROR(_xlfn.XLOOKUP(IF(LEFT(UPPER(K30),4)="REV-","REV-"&VALUE(MID(K30,5,99)),IF(LEN(K30)=5,LEFT(K30,2)&"."&RIGHT(K30,3),K30)),verfvoorraad!E:E,verfvoorraad!E:E),"Niet gevonden"))) | O30: =IF(K30="","",IFERROR(_xlfn.XLOOKUP(K30,verfvoorraad!C:C,verfvoorraad!F:F),IFERROR(_xlfn.XLOOKUP(IF(LEFT(UPPER(K30),4)="REV-","REV-"&VALUE(MID(K30,5,99)),IF(LEN(K30)=5,LEFT(K30,2)&"."&RIGHT(K30,3),K30)),verfvoorraad!E:E,verfvoorraad!F:F),"Niet gevonden"))) | P30: =IF(K30="","",IFERROR(_xlfn.XLOOKUP(K30,verfvoorraad!C:C,verfvoorraad!G:G),IFERROR(_xlfn.XLOOKUP(IF(LEFT(UPPER(K30),4)="REV-","REV-"&VALUE(MID(K30,5,99)),IF(LEN(K30)=5,LEFT(K30,2)&"."&RIGHT(K30,3),K30)),verfvoorraad!E:E,verfvoorraad!G:G),"Niet gevonden"))) | Q30: =IF(K30="","",IF(O30="Ja","Nee",IF(O30="Nee","Ja",IF(O30="Niet gevonden","Niet gevonden","")))) | R30: =IF(Q30="Ja","Toevoegen","")
B31: Model Color - German Yellow | C31: 806 | D31: Model Color | E31: 70.806 | F31: Nee | G31: 0 | H31: Nee | L31: =IF(K31="","",IFERROR(_xlfn.XLOOKUP(K31,verfvoorraad!C:C,verfvoorraad!B:B),IFERROR(_xlfn.XLOOKUP(IF(LEFT(UPPER(K31),4)="REV-","REV-"&VALUE(MID(K31,5,99)),IF(LEN(K31)=5,LEFT(K31,2)&"."&RIGHT(K31,3),K31)),verfvoorraad!E:E,verfvoorraad!B:B),"Niet gevonden"))) | M31: =IF(K31="","",IFERROR(_xlfn.XLOOKUP(K31,verfvoorraad!C:C,verfvoorraad!D:D),IFERROR(_xlfn.XLOOKUP(IF(LEFT(UPPER(K31),4)="REV-","REV-"&VALUE(MID(K31,5,99)),IF(LEN(K31)=5,LEFT(K31,2)&"."&RIGHT(K31,3),K31)),verfvoorraad!E:E,verfvoorraad!D:D),"Niet gevonden"))) | N31: =IF(K31="","",IFERROR(_xlfn.XLOOKUP(K31,verfvoorraad!C:C,verfvoorraad!E:E),IFERROR(_xlfn.XLOOKUP(IF(LEFT(UPPER(K31),4)="REV-","REV-"&VALUE(MID(K31,5,99)),IF(LEN(K31)=5,LEFT(K31,2)&"."&RIGHT(K31,3),K31)),verfvoorraad!E:E,verfvoorraad!E:E),"Niet gevonden"))) | O31: =IF(K31="","",IFERROR(_xlfn.XLOOKUP(K31,verfvoorraad!C:C,verfvoorraad!F:F),IFERROR(_xlfn.XLOOKUP(IF(LEFT(UPPER(K31),4)="REV-","REV-"&VALUE(MID(K31,5,99)),IF(LEN(K31)=5,LEFT(K31,2)&"."&RIGHT(K31,3),K31)),verfvoorraad!E:E,verfvoorraad!F:F),"Niet gevonden"))) | P31: =IF(K31="","",IFERROR(_xlfn.XLOOKUP(K31,verfvoorraad!C:C,verfvoorraad!G:G),IFERROR(_xlfn.XLOOKUP(IF(LEFT(UPPER(K31),4)="REV-","REV-"&VALUE(MID(K31,5,99)),IF(LEN(K31)=5,LEFT(K31,2)&"."&RIGHT(K31,3),K31)),verfvoorraad!E:E,verfvoorraad!G:G),"Niet gevonden"))) | Q31: =IF(K31="","",IF(O31="Ja","Nee",IF(O31="Nee","Ja",IF(O31="Niet gevonden","Niet gevonden","")))) | R31: =IF(Q31="Ja","Toevoegen","")
B32: Model Color - Ice Yellow | C32: 858 | D32: Model Color | E32: 70.858 | F32: Nee | G32: 0 | H32: Nee | L32: =IF(K32="","",IFERROR(_xlfn.XLOOKUP(K32,verfvoorraad!C:C,verfvoorraad!B:B),IFERROR(_xlfn.XLOOKUP(IF(LEFT(UPPER(K32),4)="REV-","REV-"&VALUE(MID(K32,5,99)),IF(LEN(K32)=5,LEFT(K32,2)&"."&RIGHT(K32,3),K32)),verfvoorraad!E:E,verfvoorraad!B:B),"Niet gevonden"))) | M32: =IF(K32="","",IFERROR(_xlfn.XLOOKUP(K32,verfvoorraad!C:C,verfvoorraad!D:D),IFERROR(_xlfn.XLOOKUP(IF(LEFT(UPPER(K32),4)="REV-","REV-"&VALUE(MID(K32,5,99)),IF(LEN(K32)=5,LEFT(K32,2)&"."&RIGHT(K32,3),K32)),verfvoorraad!E:E,verfvoorraad!D:D),"Niet gevonden"))) | N32: =IF(K32="","",IFERROR(_xlfn.XLOOKUP(K32,verfvoorraad!C:C,verfvoorraad!E:E),IFERROR(_xlfn.XLOOKUP(IF(LEFT(UPPER(K32),4)="REV-","REV-"&VALUE(MID(K32,5,99)),IF(LEN(K32)=5,LEFT(K32,2)&"."&RIGHT(K32,3),K32)),verfvoorraad!E:E,verfvoorraad!E:E),"Niet gevonden"))) | O32: =IF(K32="","",IFERROR(_xlfn.XLOOKUP(K32,verfvoorraad!C:C,verfvoorraad!F:F),IFERROR(_xlfn.XLOOKUP(IF(LEFT(UPPER(K32),4)="REV-","REV-"&VALUE(MID(K32,5,99)),IF(LEN(K32)=5,LEFT(K32,2)&"."&RIGHT(K32,3),K32)),verfvoorraad!E:E,verfvoorraad!F:F),"Niet gevonden"))) | P32: =IF(K32="","",IFERROR(_xlfn.XLOOKUP(K32,verfvoorraad!C:C,verfvoorraad!G:G),IFERROR(_xlfn.XLOOKUP(IF(LEFT(UPPER(K32),4)="REV-","REV-"&VALUE(MID(K32,5,99)),IF(LEN(K32)=5,LEFT(K32,2)&"."&RIGHT(K32,3),K32)),verfvoorraad!E:E,verfvoorraad!G:G),"Niet gevonden"))) | Q32: =IF(K32="","",IF(O32="Ja","Nee",IF(O32="Nee","Ja",IF(O32="Niet gevonden","Niet gevonden","")))) | R32: =IF(Q32="Ja","Toevoegen","")
B33: Model Color - Yellow Green | C33: 881 | D33: Model Color | E33: 70.881 | F33: Nee | G33: 0 | H33: Nee | L33: =IF(K33="","",IFERROR(_xlfn.XLOOKUP(K33,verfvoorraad!C:C,verfvoorraad!B:B),IFERROR(_xlfn.XLOOKUP(IF(LEFT(UPPER(K33),4)="REV-","REV-"&VALUE(MID(K33,5,99)),IF(LEN(K33)=5,LEFT(K33,2)&"."&RIGHT(K33,3),K33)),verfvoorraad!E:E,verfvoorraad!B:B),"Niet gevonden"))) | M33: =IF(K33="","",IFERROR(_xlfn.XLOOKUP(K33,verfvoorraad!C:C,verfvoorraad!D:D),IFERROR(_xlfn.XLOOKUP(IF(LEFT(UPPER(K33),4)="REV-","REV-"&VALUE(MID(K33,5,99)),IF(LEN(K33)=5,LEFT(K33,2)&"."&RIGHT(K33,3),K33)),verfvoorraad!E:E,verfvoorraad!D:D),"Niet gevonden"))) | N33: =IF(K33="","",IFERROR(_xlfn.XLOOKUP(K33,verfvoorraad!C:C,verfvoorraad!E:E),IFERROR(_xlfn.XLOOKUP(IF(LEFT(UPPER(K33),4)="REV-","REV-"&VALUE(MID(K33,5,99)),IF(LEN(K33)=5,LEFT(K33,2)&"."&RIGHT(K33,3),K33)),verfvoorraad!E:E,verfvoorraad!E:E),"Niet gevonden"))) | O33: =IF(K33="","",IFERROR(_xlfn.XLOOKUP(K33,verfvoorraad!C:C,verfvoorraad!F:F),IFERROR(_xlfn.XLOOKUP(IF(LEFT(UPPER(K33),4)="REV-","REV-"&VALUE(MID(K33,5,99)),IF(LEN(K33)=5,LEFT(K33,2)&"."&RIGHT(K33,3),K33)),verfvoorraad!E:E,verfvoorraad!F:F),"Niet gevonden"))) | P33: =IF(K33="","",IFERROR(_xlfn.XLOOKUP(K33,verfvoorraad!C:C,verfvoorraad!G:G),IFERROR(_xlfn.XLOOKUP(IF(LEFT(UPPER(K33),4)="REV-","REV-"&VALUE(MID(K33,5,99)),IF(LEN(K33)=5,LEFT(K33,2)&"."&RIGHT(K33,3),K33)),verfvoorraad!E:E,verfvoorraad!G:G),"Niet gevonden"))) | Q33: =IF(K33="","",IF(O33="Ja","Nee",IF(O33="Nee","Ja",IF(O33="Niet gevonden","Niet gevonden","")))) | R33: =IF(Q33="Ja","Toevoegen","")
B34: Model Color - Yellow Olive | C34: 892 | D34: Model Color | E34: 70.892 | F34: Nee | G34: 0 | H34: Nee | L34: =IF(K34="","",IFERROR(_xlfn.XLOOKUP(K34,verfvoorraad!C:C,verfvoorraad!B:B),IFERROR(_xlfn.XLOOKUP(IF(LEFT(UPPER(K34),4)="REV-","REV-"&VALUE(MID(K34,5,99)),IF(LEN(K34)=5,LEFT(K34,2)&"."&RIGHT(K34,3),K34)),verfvoorraad!E:E,verfvoorraad!B:B),"Niet gevonden"))) | M34: =IF(K34="","",IFERROR(_xlfn.XLOOKUP(K34,verfvoorraad!C:C,verfvoorraad!D:D),IFERROR(_xlfn.XLOOKUP(IF(LEFT(UPPER(K34),4)="REV-","REV-"&VALUE(MID(K34,5,99)),IF(LEN(K34)=5,LEFT(K34,2)&"."&RIGHT(K34,3),K34)),verfvoorraad!E:E,verfvoorraad!D:D),"Niet gevonden"))) | N34: =IF(K34="","",IFERROR(_xlfn.XLOOKUP(K34,verfvoorraad!C:C,verfvoorraad!E:E),IFERROR(_xlfn.XLOOKUP(IF(LEFT(UPPER(K34),4)="REV-","REV-"&VALUE(MID(K34,5,99)),IF(LEN(K34)=5,LEFT(K34,2)&"."&RIGHT(K34,3),K34)),verfvoorraad!E:E,verfvoorraad!E:E),"Niet gevonden"))) | O34: =IF(K34="","",IFERROR(_xlfn.XLOOKUP(K34,verfvoorraad!C:C,verfvoorraad!F:F),IFERROR(_xlfn.XLOOKUP(IF(LEFT(UPPER(K34),4)="REV-","REV-"&VALUE(MID(K34,5,99)),IF(LEN(K34)=5,LEFT(K34,2)&"."&RIGHT(K34,3),K34)),verfvoorraad!E:E,verfvoorraad!F:F),"Niet gevonden"))) | P34: =IF(K34="","",IFERROR(_xlfn.XLOOKUP(K34,verfvoorraad!C:C,verfvoorraad!G:G),IFERROR(_xlfn.XLOOKUP(IF(LEFT(UPPER(K34),4)="REV-","REV-"&VALUE(MID(K34,5,99)),IF(LEN(K34)=5,LEFT(K34,2)&"."&RIGHT(K34,3),K34)),verfvoorraad!E:E,verfvoorraad!G:G),"Niet gevonden"))) | Q34: =IF(K34="","",IF(O34="Ja","Nee",IF(O34="Nee","Ja",IF(O34="Niet gevonden","Niet gevonden","")))) | R34: =IF(Q34="Ja","Toevoegen","")
B35: Model Color - Tan Yellow | C35: 912 | D35: Model Color | E35: 70.912 | F35: Nee | G35: 0 | H35: Nee | L35: =IF(K35="","",IFERROR(_xlfn.XLOOKUP(K35,verfvoorraad!C:C,verfvoorraad!B:B),IFERROR(_xlfn.XLOOKUP(IF(LEFT(UPPER(K35),4)="REV-","REV-"&VALUE(MID(K35,5,99)),IF(LEN(K35)=5,LEFT(K35,2)&"."&RIGHT(K35,3),K35)),verfvoorraad!E:E,verfvoorraad!B:B),"Niet gevonden"))) | M35: =IF(K35="","",IFERROR(_xlfn.XLOOKUP(K35,verfvoorraad!C:C,verfvoorraad!D:D),IFERROR(_xlfn.XLOOKUP(IF(LEFT(UPPER(K35),4)="REV-","REV-"&VALUE(MID(K35,5,99)),IF(LEN(K35)=5,LEFT(K35,2)&"."&RIGHT(K35,3),K35)),verfvoorraad!E:E,verfvoorraad!D:D),"Niet gevonden"))) | N35: =IF(K35="","",IFERROR(_xlfn.XLOOKUP(K35,verfvoorraad!C:C,verfvoorraad!E:E),IFERROR(_xlfn.XLOOKUP(IF(LEFT(UPPER(K35),4)="REV-","REV-"&VALUE(MID(K35,5,99)),IF(LEN(K35)=5,LEFT(K35,2)&"."&RIGHT(K35,3),K35)),verfvoorraad!E:E,verfvoorraad!E:E),"Niet gevonden"))) | O35: =IF(K35="","",IFERROR(_xlfn.XLOOKUP(K35,verfvoorraad!C:C,verfvoorraad!F:F),IFERROR(_xlfn.XLOOKUP(IF(LEFT(UPPER(K35),4)="REV-","REV-"&VALUE(MID(K35,5,99)),IF(LEN(K35)=5,LEFT(K35,2)&"."&RIGHT(K35,3),K35)),verfvoorraad!E:E,verfvoorraad!F:F),"Niet gevonden"))) | P35: =IF(K35="","",IFERROR(_xlfn.XLOOKUP(K35,verfvoorraad!C:C,verfvoorraad!G:G),IFERROR(_xlfn.XLOOKUP(IF(LEFT(UPPER(K35),4)="REV-","REV-"&VALUE(MID(K35,5,99)),IF(LEN(K35)=5,LEFT(K35,2)&"."&RIGHT(K35,3),K35)),verfvoorraad!E:E,verfvoorraad!G:G),"Niet gevonden"))) | Q35: =IF(K35="","",IF(O35="Ja","Nee",IF(O35="Nee","Ja",IF(O35="Niet gevonden","Niet gevonden","")))) | R35: =IF(Q35="Ja","Toevoegen","")
B36: Model Color - Yellow Ochre | C36: 913 | D36: Model Color | E36: 70.913 | F36: Nee | G36: 0 | H36: Nee | L36: =IF(K36="","",IFERROR(_xlfn.XLOOKUP(K36,verfvoorraad!C:C,verfvoorraad!B:B),IFERROR(_xlfn.XLOOKUP(IF(LEFT(UPPER(K36),4)="REV-","REV-"&VALUE(MID(K36,5,99)),IF(LEN(K36)=5,LEFT(K36,2)&"."&RIGHT(K36,3),K36)),verfvoorraad!E:E,verfvoorraad!B:B),"Niet gevonden"))) | M36: =IF(K36="","",IFERROR(_xlfn.XLOOKUP(K36,verfvoorraad!C:C,verfvoorraad!D:D),IFERROR(_xlfn.XLOOKUP(IF(LEFT(UPPER(K36),4)="REV-","REV-"&VALUE(MID(K36,5,99)),IF(LEN(K36)=5,LEFT(K36,2)&"."&RIGHT(K36,3),K36)),verfvoorraad!E:E,verfvoorraad!D:D),"Niet gevonden"))) | N36: =IF(K36="","",IFERROR(_xlfn.XLOOKUP(K36,verfvoorraad!C:C,verfvoorraad!E:E),IFERROR(_xlfn.XLOOKUP(IF(LEFT(UPPER(K36),4)="REV-","REV-"&VALUE(MID(K36,5,99)),IF(LEN(K36)=5,LEFT(K36,2)&"."&RIGHT(K36,3),K36)),verfvoorraad!E:E,verfvoorraad!E:E),"Niet gevonden"))) | O36: =IF(K36="","",IFERROR(_xlfn.XLOOKUP(K36,verfvoorraad!C:C,verfvoorraad!F:F),IFERROR(_xlfn.XLOOKUP(IF(LEFT(UPPER(K36),4)="REV-","REV-"&VALUE(MID(K36,5,99)),IF(LEN(K36)=5,LEFT(K36,2)&"."&RIGHT(K36,3),K36)),verfvoorraad!E:E,verfvoorraad!F:F),"Niet gevonden"))) | P36: =IF(K36="","",IFERROR(_xlfn.XLOOKUP(K36,verfvoorraad!C:C,verfvoorraad!G:G),IFERROR(_xlfn.XLOOKUP(IF(LEFT(UPPER(K36),4)="REV-","REV-"&VALUE(MID(K36,5,99)),IF(LEN(K36)=5,LEFT(K36,2)&"."&RIGHT(K36,3),K36)),verfvoorraad!E:E,verfvoorraad!G:G),"Niet gevonden"))) | Q36: =IF(K36="","",IF(O36="Ja","Nee",IF(O36="Nee","Ja",IF(O36="Niet gevonden","Niet gevonden","")))) | R36: =IF(Q36="Ja","Toevoegen","")
B37: Model Color - Deep Yellow | C37: 915 | D37: Model Color | E37: 70.915 | F37: Nee | G37: 0 | H37: Nee | L37: =IF(K37="","",IFERROR(_xlfn.XLOOKUP(K37,verfvoorraad!C:C,verfvoorraad!B:B),IFERROR(_xlfn.XLOOKUP(IF(LEFT(UPPER(K37),4)="REV-","REV-"&VALUE(MID(K37,5,99)),IF(LEN(K37)=5,LEFT(K37,2)&"."&RIGHT(K37,3),K37)),verfvoorraad!E:E,verfvoorraad!B:B),"Niet gevonden"))) | M37: =IF(K37="","",IFERROR(_xlfn.XLOOKUP(K37,verfvoorraad!C:C,verfvoorraad!D:D),IFERROR(_xlfn.XLOOKUP(IF(LEFT(UPPER(K37),4)="REV-","REV-"&VALUE(MID(K37,5,99)),IF(LEN(K37)=5,LEFT(K37,2)&"."&RIGHT(K37,3),K37)),verfvoorraad!E:E,verfvoorraad!D:D),"Niet gevonden"))) | N37: =IF(K37="","",IFERROR(_xlfn.XLOOKUP(K37,verfvoorraad!C:C,verfvoorraad!E:E),IFERROR(_xlfn.XLOOKUP(IF(LEFT(UPPER(K37),4)="REV-","REV-"&VALUE(MID(K37,5,99)),IF(LEN(K37)=5,LEFT(K37,2)&"."&RIGHT(K37,3),K37)),verfvoorraad!E:E,verfvoorraad!E:E),"Niet gevonden"))) | O37: =IF(K37="","",IFERROR(_xlfn.XLOOKUP(K37,verfvoorraad!C:C,verfvoorraad!F:F),IFERROR(_xlfn.XLOOKUP(IF(LEFT(UPPER(K37),4)="REV-","REV-"&VALUE(MID(K37,5,99)),IF(LEN(K37)=5,LEFT(K37,2)&"."&RIGHT(K37,3),K37)),verfvoorraad!E:E,verfvoorraad!F:F),"Niet gevonden"))) | P37: =IF(K37="","",IFERROR(_xlfn.XLOOKUP(K37,verfvoorraad!C:C,verfvoorraad!G:G),IFERROR(_xlfn.XLOOKUP(IF(LEFT(UPPER(K37),4)="REV-","REV-"&VALUE(MID(K37,5,99)),IF(LEN(K37)=5,LEFT(K37,2)&"."&RIGHT(K37,3),K37)),verfvoorraad!E:E,verfvoorraad!G:G),"Niet gevonden"))) | Q37: =IF(K37="","",IF(O37="Ja","Nee",IF(O37="Nee","Ja",IF(O37="Niet gevonden","Niet gevonden","")))) | R37: =IF(Q37="Ja","Toevoegen","")
B38: Model Color - Sand Yellow | C38: 916 | D38: Model Color | E38: 70.916 | F38: Nee | G38: 0 | H38: Nee | L38: =IF(K38="","",IFERROR(_xlfn.XLOOKUP(K38,verfvoorraad!C:C,verfvoorraad!B:B),IFERROR(_xlfn.XLOOKUP(IF(LEFT(UPPER(K38),4)="REV-","REV-"&VALUE(MID(K38,5,99)),IF(LEN(K38)=5,LEFT(K38,2)&"."&RIGHT(K38,3),K38)),verfvoorraad!E:E,verfvoorraad!B:B),"Niet gevonden"))) | M38: =IF(K38="","",IFERROR(_xlfn.XLOOKUP(K38,verfvoorraad!C:C,verfvoorraad!D:D),IFERROR(_xlfn.XLOOKUP(IF(LEFT(UPPER(K38),4)="REV-","REV-"&VALUE(MID(K38,5,99)),IF(LEN(K38)=5,LEFT(K38,2)&"."&RIGHT(K38,3),K38)),verfvoorraad!E:E,verfvoorraad!D:D),"Niet gevonden"))) | N38: =IF(K38="","",IFERROR(_xlfn.XLOOKUP(K38,verfvoorraad!C:C,verfvoorraad!E:E),IFERROR(_xlfn.XLOOKUP(IF(LEFT(UPPER(K38),4)="REV-","REV-"&VALUE(MID(K38,5,99)),IF(LEN(K38)=5,LEFT(K38,2)&"."&RIGHT(K38,3),K38)),verfvoorraad!E:E,verfvoorraad!E:E),"Niet gevonden"))) | O38: =IF(K38="","",IFERROR(_xlfn.XLOOKUP(K38,verfvoorraad!C:C,verfvoorraad!F:F),IFERROR(_xlfn.XLOOKUP(IF(LEFT(UPPER(K38),4)="REV-","REV-"&VALUE(MID(K38,5,99)),IF(LEN(K38)=5,LEFT(K38,2)&"."&RIGHT(K38,3),K38)),verfvoorraad!E:E,verfvoorraad!F:F),"Niet gevonden"))) | P38: =IF(K38="","",IFERROR(_xlfn.XLOOKUP(K38,verfvoorraad!C:C,verfvoorraad!G:G),IFERROR(_xlfn.XLOOKUP(IF(LEFT(UPPER(K38),4)="REV-","REV-"&VALUE(MID(K38,5,99)),IF(LEN(K38)=5,LEFT(K38,2)&"."&RIGHT(K38,3),K38)),verfvoorraad!E:E,verfvoorraad!G:G),"Niet gevonden"))) | Q38: =IF(K38="","",IF(O38="Ja","Nee",IF(O38="Nee","Ja",IF(O38="Niet gevonden","Niet gevonden","")))) | R38: =IF(Q38="Ja","Toevoegen","")
B39: Model Color - Transparent Yellow | C39: 937 | D39: Model Color | E39: 70.937 | F39: Nee | G39: 0 | H39: Nee | L39: =IF(K39="","",IFERROR(_xlfn.XLOOKUP(K39,verfvoorraad!C:C,verfvoorraad!B:B),IFERROR(_xlfn.XLOOKUP(IF(LEFT(UPPER(K39),4)="REV-","REV-"&VALUE(MID(K39,5,99)),IF(LEN(K39)=5,LEFT(K39,2)&"."&RIGHT(K39,3),K39)),verfvoorraad!E:E,verfvoorraad!B:B),"Niet gevonden"))) | M39: =IF(K39="","",IFERROR(_xlfn.XLOOKUP(K39,verfvoorraad!C:C,verfvoorraad!D:D),IFERROR(_xlfn.XLOOKUP(IF(LEFT(UPPER(K39),4)="REV-","REV-"&VALUE(MID(K39,5,99)),IF(LEN(K39)=5,LEFT(K39,2)&"."&RIGHT(K39,3),K39)),verfvoorraad!E:E,verfvoorraad!D:D),"Niet gevonden"))) | N39: =IF(K39="","",IFERROR(_xlfn.XLOOKUP(K39,verfvoorraad!C:C,verfvoorraad!E:E),IFERROR(_xlfn.XLOOKUP(IF(LEFT(UPPER(K39),4)="REV-","REV-"&VALUE(MID(K39,5,99)),IF(LEN(K39)=5,LEFT(K39,2)&"."&RIGHT(K39,3),K39)),verfvoorraad!E:E,verfvoorraad!E:E),"Niet gevonden"))) | O39: =IF(K39="","",IFERROR(_xlfn.XLOOKUP(K39,verfvoorraad!C:C,verfvoorraad!F:F),IFERROR(_xlfn.XLOOKUP(IF(LEFT(UPPER(K39),4)="REV-","REV-"&VALUE(MID(K39,5,99)),IF(LEN(K39)=5,LEFT(K39,2)&"."&RIGHT(K39,3),K39)),verfvoorraad!E:E,verfvoorraad!F:F),"Niet gevonden"))) | P39: =IF(K39="","",IFERROR(_xlfn.XLOOKUP(K39,verfvoorraad!C:C,verfvoorraad!G:G),IFERROR(_xlfn.XLOOKUP(IF(LEFT(UPPER(K39),4)="REV-","REV-"&VALUE(MID(K39,5,99)),IF(LEN(K39)=5,LEFT(K39,2)&"."&RIGHT(K39,3),K39)),verfvoorraad!E:E,verfvoorraad!G:G),"Niet gevonden"))) | Q39: =IF(K39="","",IF(O39="Ja","Nee",IF(O39="Nee","Ja",IF(O39="Niet gevonden","Niet gevonden","")))) | R39: =IF(Q39="Ja","Toevoegen","")
B40: Model Color - Golden Yellow | C40: 948 | D40: Model Color | E40: 70.948 | F40: Nee | G40: 0 | H40: Nee | L40: =IF(K40="","",IFERROR(_xlfn.XLOOKUP(K40,verfvoorraad!C:C,verfvoorraad!B:B),IFERROR(_xlfn.XLOOKUP(IF(LEFT(UPPER(K40),4)="REV-","REV-"&VALUE(MID(K40,5,99)),IF(LEN(K40)=5,LEFT(K40,2)&"."&RIGHT(K40,3),K40)),verfvoorraad!E:E,verfvoorraad!B:B),"Niet gevonden"))) | M40: =IF(K40="","",IFERROR(_xlfn.XLOOKUP(K40,verfvoorraad!C:C,verfvoorraad!D:D),IFERROR(_xlfn.XLOOKUP(IF(LEFT(UPPER(K40),4)="REV-","REV-"&VALUE(MID(K40,5,99)),IF(LEN(K40)=5,LEFT(K40,2)&"."&RIGHT(K40,3),K40)),verfvoorraad!E:E,verfvoorraad!D:D),"Niet gevonden"))) | N40: =IF(K40="","",IFERROR(_xlfn.XLOOKUP(K40,verfvoorraad!C:C,verfvoorraad!E:E),IFERROR(_xlfn.XLOOKUP(IF(LEFT(UPPER(K40),4)="REV-","REV-"&VALUE(MID(K40,5,99)),IF(LEN(K40)=5,LEFT(K40,2)&"."&RIGHT(K40,3),K40)),verfvoorraad!E:E,verfvoorraad!E:E),"Niet gevonden"))) | O40: =IF(K40="","",IFERROR(_xlfn.XLOOKUP(K40,verfvoorraad!C:C,verfvoorraad!F:F),IFERROR(_xlfn.XLOOKUP(IF(LEFT(UPPER(K40),4)="REV-","REV-"&VALUE(MID(K40,5,99)),IF(LEN(K40)=5,LEFT(K40,2)&"."&RIGHT(K40,3),K40)),verfvoorraad!E:E,verfvoorraad!F:F),"Niet gevonden"))) | P40: =IF(K40="","",IFERROR(_xlfn.XLOOKUP(K40,verfvoorraad!C:C,verfvoorraad!G:G),IFERROR(_xlfn.XLOOKUP(IF(LEFT(UPPER(K40),4)="REV-","REV-"&VALUE(MID(K40,5,99)),IF(LEN(K40)=5,LEFT(K40,2)&"."&RIGHT(K40,3),K40)),verfvoorraad!E:E,verfvoorraad!G:G),"Niet gevonden"))) | Q40: =IF(K40="","",IF(O40="Ja","Nee",IF(O40="Nee","Ja",IF(O40="Niet gevonden","Niet gevonden","")))) | R40: =IF(Q40="Ja","Toevoegen","")
B41: Model Color - Light Yellow | C41: 949 | D41: Model Color | E41: 70.949 | F41: Nee | G41: 0 | H41: Nee | L41: =IF(K41="","",IFERROR(_xlfn.XLOOKUP(K41,verfvoorraad!C:C,verfvoorraad!B:B),IFERROR(_xlfn.XLOOKUP(IF(LEFT(UPPER(K41),4)="REV-","REV-"&VALUE(MID(K41,5,99)),IF(LEN(K41)=5,LEFT(K41,2)&"."&RIGHT(K41,3),K41)),verfvoorraad!E:E,verfvoorraad!B:B),"Niet gevonden"))) | M41: =IF(K41="","",IFERROR(_xlfn.XLOOKUP(K41,verfvoorraad!C:C,verfvoorraad!D:D),IFERROR(_xlfn.XLOOKUP(IF(LEFT(UPPER(K41),4)="REV-","REV-"&VALUE(MID(K41,5,99)),IF(LEN(K41)=5,LEFT(K41,2)&"."&RIGHT(K41,3),K41)),verfvoorraad!E:E,verfvoorraad!D:D),"Niet gevonden"))) | N41: =IF(K41="","",IFERROR(_xlfn.XLOOKUP(K41,verfvoorraad!C:C,verfvoorraad!E:E),IFERROR(_xlfn.XLOOKUP(IF(LEFT(UPPER(K41),4)="REV-","REV-"&VALUE(MID(K41,5,99)),IF(LEN(K41)=5,LEFT(K41,2)&"."&RIGHT(K41,3),K41)),verfvoorraad!E:E,verfvoorraad!E:E),"Niet gevonden"))) | O41: =IF(K41="","",IFERROR(_xlfn.XLOOKUP(K41,verfvoorraad!C:C,verfvoorraad!F:F),IFERROR(_xlfn.XLOOKUP(IF(LEFT(UPPER(K41),4)="REV-","REV-"&VALUE(MID(K41,5,99)),IF(LEN(K41)=5,LEFT(K41,2)&"."&RIGHT(K41,3),K41)),verfvoorraad!E:E,verfvoorraad!F:F),"Niet gevonden"))) | P41: =IF(K41="","",IFERROR(_xlfn.XLOOKUP(K41,verfvoorraad!C:C,verfvoorraad!G:G),IFERROR(_xlfn.XLOOKUP(IF(LEFT(UPPER(K41),4)="REV-","REV-"&VALUE(MID(K41,5,99)),IF(LEN(K41)=5,LEFT(K41,2)&"."&RIGHT(K41,3),K41)),verfvoorraad!E:E,verfvoorraad!G:G),"Niet gevonden"))) | Q41: =IF(K41="","",IF(O41="Ja","Nee",IF(O41="Nee","Ja",IF(O41="Niet gevonden","Niet gevonden","")))) | R41: =IF(Q41="Ja","Toevoegen","")
... B49: Semi Gloss Luminous Yellow | C49: 312 | D49: Enamel Revell | E49: REV-312 | F49: Nee | G49: 0 | H49: Nee | L49: =IF(K49="","",IFERROR(_xlfn.XLOOKUP(K49,verfvoorraad!C:C,verfvoorraad!B:B),IFERROR(_xlfn.XLOOKUP(IF(LEFT(UPPER(K49),4)="REV-","REV-"&VALUE(MID(K49,5,99)),IF(LEN(K49)=5,LEFT(K49,2)&"."&RIGHT(K49,3),K49)),verfvoorraad!E:E,verfvoorraad!B:B),"Niet gevonden"))) | M49: =IF(K49="","",IFERROR(_xlfn.XLOOKUP(K49,verfvoorraad!C:C,verfvoorraad!D:D),IFERROR(_xlfn.XLOOKUP(IF(LEFT(UPPER(K49),4)="REV-","REV-"&VALUE(MID(K49,5,99)),IF(LEN(K49)=5,LEFT(K49,2)&"."&RIGHT(K49,3),K49)),verfvoorraad!E:E,verfvoorraad!D:D),"Niet gevonden"))) | N49: =IF(K49="","",IFERROR(_xlfn.XLOOKUP(K49,verfvoorraad!C:C,verfvoorraad!E:E),IFERROR(_xlfn.XLOOKUP(IF(LEFT(UPPER(K49),4)="REV-","REV-"&VALUE(MID(K49,5,99)),IF(LEN(K49)=5,LEFT(K49,2)&"."&RIGHT(K49,3),K49)),verfvoorraad!E:E,verfvoorraad!E:E),"Niet gevonden"))) | O49: =IF(K49="","",IFERROR(_xlfn.XLOOKUP(K49,verfvoorraad!C:C,verfvoorraad!F:F),IFERROR(_xlfn.XLOOKUP(IF(LEFT(UPPER(K49),4)="REV-","REV-"&VALUE(MID(K49,5,99)),IF(LEN(K49)=5,LEFT(K49,2)&"."&RIGHT(K49,3),K49)),verfvoorraad!E:E,verfvoorraad!F:F),"Niet gevonden"))) | P49: =IF(K49="","",IFERROR(_xlfn.XLOOKUP(K49,verfvoorraad!C:C,verfvoorraad!G:G),IFERROR(_xlfn.XLOOKUP(IF(LEFT(UPPER(K49),4)="REV-","REV-"&VALUE(MID(K49,5,99)),IF(LEN(K49)=5,LEFT(K49,2)&"."&RIGHT(K49,3),K49)),verfvoorraad!E:E,verfvoorraad!G:G),"Niet gevonden"))) | Q49: =IF(K49="","",IF(O49="Ja","Nee",IF(O49="Nee","Ja",IF(O49="Niet gevonden","Niet gevonden","")))) | R49: =IF(Q49="Ja","Toevoegen","")
L50: =IF(K50="","",IFERROR(_xlfn.XLOOKUP(K50,verfvoorraad!C:C,verfvoorraad!B:B),IFERROR(_xlfn.XLOOKUP(IF(LEFT(UPPER(K50),4)="REV-","REV-"&VALUE(MID(K50,5,99)),IF(LEN(K50)=5,LEFT(K50,2)&"."&RIGHT(K50,3),K50)),verfvoorraad!E:E,verfvoorraad!B:B),"Niet gevonden"))) | M50: =IF(K50="","",IFERROR(_xlfn.XLOOKUP(K50,verfvoorraad!C:C,verfvoorraad!D:D),IFERROR(_xlfn.XLOOKUP(IF(LEFT(UPPER(K50),4)="REV-","REV-"&VALUE(MID(K50,5,99)),IF(LEN(K50)=5,LEFT(K50,2)&"."&RIGHT(K50,3),K50)),verfvoorraad!E:E,verfvoorraad!D:D),"Niet gevonden"))) | N50: =IF(K50="","",IFERROR(_xlfn.XLOOKUP(K50,verfvoorraad!C:C,verfvoorraad!E:E),IFERROR(_xlfn.XLOOKUP(IF(LEFT(UPPER(K50),4)="REV-","REV-"&VALUE(MID(K50,5,99)),IF(LEN(K50)=5,LEFT(K50,2)&"."&RIGHT(K50,3),K50)),verfvoorraad!E:E,verfvoorraad!E:E),"Niet gevonden"))) | O50: =IF(K50="","",IFERROR(_xlfn.XLOOKUP(K50,verfvoorraad!C:C,verfvoorraad!F:F),IFERROR(_xlfn.XLOOKUP(IF(LEFT(UPPER(K50),4)="REV-","REV-"&VALUE(MID(K50,5,99)),IF(LEN(K50)=5,LEFT(K50,2)&"."&RIGHT(K50,3),K50)),verfvoorraad!E:E,verfvoorraad!F:F),"Niet gevonden"))) | P50: =IF(K50="","",IFERROR(_xlfn.XLOOKUP(K50,verfvoorraad!C:C,verfvoorraad!G:G),IFERROR(_xlfn.XLOOKUP(IF(LEFT(UPPER(K50),4)="REV-","REV-"&VALUE(MID(K50,5,99)),IF(LEN(K50)=5,LEFT(K50,2)&"."&RIGHT(K50,3),K50)),verfvoorraad!E:E,verfvoorraad!G:G),"Niet gevonden"))) | Q50: =IF(K50="","",IF(O50="Ja","Nee",IF(O50="Nee","Ja",IF(O50="Niet gevonden","Niet gevonden","")))) | R50: =IF(Q50="Ja","Toevoegen","")
L51: =IF(K51="","",IFERROR(_xlfn.XLOOKUP(K51,verfvoorraad!C:C,verfvoorraad!B:B),IFERROR(_xlfn.XLOOKUP(IF(LEFT(UPPER(K51),4)="REV-","REV-"&VALUE(MID(K51,5,99)),IF(LEN(K51)=5,LEFT(K51,2)&"."&RIGHT(K51,3),K51)),verfvoorraad!E:E,verfvoorraad!B:B),"Niet gevonden"))) | M51: =IF(K51="","",IFERROR(_xlfn.XLOOKUP(K51,verfvoorraad!C:C,verfvoorraad!D:D),IFERROR(_xlfn.XLOOKUP(IF(LEFT(UPPER(K51),4)="REV-","REV-"&VALUE(MID(K51,5,99)),IF(LEN(K51)=5,LEFT(K51,2)&"."&RIGHT(K51,3),K51)),verfvoorraad!E:E,verfvoorraad!D:D),"Niet gevonden"))) | N51: =IF(K51="","",IFERROR(_xlfn.XLOOKUP(K51,verfvoorraad!C:C,verfvoorraad!E:E),IFERROR(_xlfn.XLOOKUP(IF(LEFT(UPPER(K51),4)="REV-","REV-"&VALUE(MID(K51,5,99)),IF(LEN(K51)=5,LEFT(K51,2)&"."&RIGHT(K51,3),K51)),verfvoorraad!E:E,verfvoorraad!E:E),"Niet gevonden"))) | O51: =IF(K51="","",IFERROR(_xlfn.XLOOKUP(K51,verfvoorraad!C:C,verfvoorraad!F:F),IFERROR(_xlfn.XLOOKUP(IF(LEFT(UPPER(K51),4)="REV-","REV-"&VALUE(MID(K51,5,99)),IF(LEN(K51)=5,LEFT(K51,2)&"."&RIGHT(K51,3),K51)),verfvoorraad!E:E,verfvoorraad!F:F),"Niet gevonden"))) | P51: =IF(K51="","",IFERROR(_xlfn.XLOOKUP(K51,verfvoorraad!C:C,verfvoorraad!G:G),IFERROR(_xlfn.XLOOKUP(IF(LEFT(UPPER(K51),4)="REV-","REV-"&VALUE(MID(K51,5,99)),IF(LEN(K51)=5,LEFT(K51,2)&"."&RIGHT(K51,3),K51)),verfvoorraad!E:E,verfvoorraad!G:G),"Niet gevonden"))) | Q51: =IF(K51="","",IF(O51="Ja","Nee",IF(O51="Nee","Ja",IF(O51="Niet gevonden","Niet gevonden","")))) | R51: =IF(Q51="Ja","Toevoegen","")
L52: =IF(K52="","",IFERROR(_xlfn.XLOOKUP(K52,verfvoorraad!C:C,verfvoorraad!B:B),IFERROR(_xlfn.XLOOKUP(IF(LEFT(UPPER(K52),4)="REV-","REV-"&VALUE(MID(K52,5,99)),IF(LEN(K52)=5,LEFT(K52,2)&"."&RIGHT(K52,3),K52)),verfvoorraad!E:E,verfvoorraad!B:B),"Niet gevonden"))) | M52: =IF(K52="","",IFERROR(_xlfn.XLOOKUP(K52,verfvoorraad!C:C,verfvoorraad!D:D),IFERROR(_xlfn.XLOOKUP(IF(LEFT(UPPER(K52),4)="REV-","REV-"&VALUE(MID(K52,5,99)),IF(LEN(K52)=5,LEFT(K52,2)&"."&RIGHT(K52,3),K52)),verfvoorraad!E:E,verfvoorraad!D:D),"Niet gevonden"))) | N52: =IF(K52="","",IFERROR(_xlfn.XLOOKUP(K52,verfvoorraad!C:C,verfvoorraad!E:E),IFERROR(_xlfn.XLOOKUP(IF(LEFT(UPPER(K52),4)="REV-","REV-"&VALUE(MID(K52,5,99)),IF(LEN(K52)=5,LEFT(K52,2)&"."&RIGHT(K52,3),K52)),verfvoorraad!E:E,verfvoorraad!E:E),"Niet gevonden"))) | O52: =IF(K52="","",IFERROR(_xlfn.XLOOKUP(K52,verfvoorraad!C:C,verfvoorraad!F:F),IFERROR(_xlfn.XLOOKUP(IF(LEFT(UPPER(K52),4)="REV-","REV-"&VALUE(MID(K52,5,99)),IF(LEN(K52)=5,LEFT(K52,2)&"."&RIGHT(K52,3),K52)),verfvoorraad!E:E,verfvoorraad!F:F),"Niet gevonden"))) | P52: =IF(K52="","",IFERROR(_xlfn.XLOOKUP(K52,verfvoorraad!C:C,verfvoorraad!G:G),IFERROR(_xlfn.XLOOKUP(IF(LEFT(UPPER(K52),4)="REV-","REV-"&VALUE(MID(K52,5,99)),IF(LEN(K52)=5,LEFT(K52,2)&"."&RIGHT(K52,3),K52)),verfvoorraad!E:E,verfvoorraad!G:G),"Niet gevonden"))) | Q52: =IF(K52="","",IF(O52="Ja","Nee",IF(O52="Nee","Ja",IF(O52="Niet gevonden","Niet gevonden","")))) | R52: =IF(Q52="Ja","Toevoegen","")
L53: =IF(K53="","",IFERROR(_xlfn.XLOOKUP(K53,verfvoorraad!C:C,verfvoorraad!B:B),IFERROR(_xlfn.XLOOKUP(IF(LEFT(UPPER(K53),4)="REV-","REV-"&VALUE(MID(K53,5,99)),IF(LEN(K53)=5,LEFT(K53,2)&"."&RIGHT(K53,3),K53)),verfvoorraad!E:E,verfvoorraad!B:B),"Niet gevonden"))) | M53: =IF(K53="","",IFERROR(_xlfn.XLOOKUP(K53,verfvoorraad!C:C,verfvoorraad!D:D),IFERROR(_xlfn.XLOOKUP(IF(LEFT(UPPER(K53),4)="REV-","REV-"&VALUE(MID(K53,5,99)),IF(LEN(K53)=5,LEFT(K53,2)&"."&RIGHT(K53,3),K53)),verfvoorraad!E:E,verfvoorraad!D:D),"Niet gevonden"))) | N53: =IF(K53="","",IFERROR(_xlfn.XLOOKUP(K53,verfvoorraad!C:C,verfvoorraad!E:E),IFERROR(_xlfn.XLOOKUP(IF(LEFT(UPPER(K53),4)="REV-","REV-"&VALUE(MID(K53,5,99)),IF(LEN(K53)=5,LEFT(K53,2)&"."&RIGHT(K53,3),K53)),verfvoorraad!E:E,verfvoorraad!E:E),"Niet gevonden"))) | O53: =IF(K53="","",IFERROR(_xlfn.XLOOKUP(K53,verfvoorraad!C:C,verfvoorraad!F:F),IFERROR(_xlfn.XLOOKUP(IF(LEFT(UPPER(K53),4)="REV-","REV-"&VALUE(MID(K53,5,99)),IF(LEN(K53)=5,LEFT(K53,2)&"."&RIGHT(K53,3),K53)),verfvoorraad!E:E,verfvoorraad!F:F),"Niet gevonden"))) | P53: =IF(K53="","",IFERROR(_xlfn.XLOOKUP(K53,verfvoorraad!C:C,verfvoorraad!G:G),IFERROR(_xlfn.XLOOKUP(IF(LEFT(UPPER(K53),4)="REV-","REV-"&VALUE(MID(K53,5,99)),IF(LEN(K53)=5,LEFT(K53,2)&"."&RIGHT(K53,3),K53)),verfvoorraad!E:E,verfvoorraad!G:G),"Niet gevonden"))) | Q53: =IF(K53="","",IF(O53="Ja","Nee",IF(O53="Nee","Ja",IF(O53="Niet gevonden","Niet gevonden","")))) | R53: =IF(Q53="Ja","Toevoegen","")
L54: =IF(K54="","",IFERROR(_xlfn.XLOOKUP(K54,verfvoorraad!C:C,verfvoorraad!B:B),IFERROR(_xlfn.XLOOKUP(IF(LEFT(UPPER(K54),4)="REV-","REV-"&VALUE(MID(K54,5,99)),IF(LEN(K54)=5,LEFT(K54,2)&"."&RIGHT(K54,3),K54)),verfvoorraad!E:E,verfvoorraad!B:B),"Niet gevonden"))) | M54: =IF(K54="","",IFERROR(_xlfn.XLOOKUP(K54,verfvoorraad!C:C,verfvoorraad!D:D),IFERROR(_xlfn.XLOOKUP(IF(LEFT(UPPER(K54),4)="REV-","REV-"&VALUE(MID(K54,5,99)),IF(LEN(K54)=5,LEFT(K54,2)&"."&RIGHT(K54,3),K54)),verfvoorraad!E:E,verfvoorraad!D:D),"Niet gevonden"))) | N54: =IF(K54="","",IFERROR(_xlfn.XLOOKUP(K54,verfvoorraad!C:C,verfvoorraad!E:E),IFERROR(_xlfn.XLOOKUP(IF(LEFT(UPPER(K54),4)="REV-","REV-"&VALUE(MID(K54,5,99)),IF(LEN(K54)=5,LEFT(K54,2)&"."&RIGHT(K54,3),K54)),verfvoorraad!E:E,verfvoorraad!E:E),"Niet gevonden"))) | O54: =IF(K54="","",IFERROR(_xlfn.XLOOKUP(K54,verfvoorraad!C:C,verfvoorraad!F:F),IFERROR(_xlfn.XLOOKUP(IF(LEFT(UPPER(K54),4)="REV-","REV-"&VALUE(MID(K54,5,99)),IF(LEN(K54)=5,LEFT(K54,2)&"."&RIGHT(K54,3),K54)),verfvoorraad!E:E,verfvoorraad!F:F),"Niet gevonden"))) | P54: =IF(K54="","",IFERROR(_xlfn.XLOOKUP(K54,verfvoorraad!C:C,verfvoorraad!G:G),IFERROR(_xlfn.XLOOKUP(IF(LEFT(UPPER(K54),4)="REV-","REV-"&VALUE(MID(K54,5,99)),IF(LEN(K54)=5,LEFT(K54,2)&"."&RIGHT(K54,3),K54)),verfvoorraad!E:E,verfvoorraad!G:G),"Niet gevonden"))) | Q54: =IF(K54="","",IF(O54="Ja","Nee",IF(O54="Nee","Ja",IF(O54="Niet gevonden","Niet gevonden","")))) | R54: =IF(Q54="Ja","Toevoegen","")
L55: =IF(K55="","",IFERROR(_xlfn.XLOOKUP(K55,verfvoorraad!C:C,verfvoorraad!B:B),IFERROR(_xlfn.XLOOKUP(IF(LEFT(UPPER(K55),4)="REV-","REV-"&VALUE(MID(K55,5,99)),IF(LEN(K55)=5,LEFT(K55,2)&"."&RIGHT(K55,3),K55)),verfvoorraad!E:E,verfvoorraad!B:B),"Niet gevonden"))) | M55: =IF(K55="","",IFERROR(_xlfn.XLOOKUP(K55,verfvoorraad!C:C,verfvoorraad!D:D),IFERROR(_xlfn.XLOOKUP(IF(LEFT(UPPER(K55),4)="REV-","REV-"&VALUE(MID(K55,5,99)),IF(LEN(K55)=5,LEFT(K55,2)&"."&RIGHT(K55,3),K55)),verfvoorraad!E:E,verfvoorraad!D:D),"Niet gevonden"))) | N55: =IF(K55="","",IFERROR(_xlfn.XLOOKUP(K55,verfvoorraad!C:C,verfvoorraad!E:E),IFERROR(_xlfn.XLOOKUP(IF(LEFT(UPPER(K55),4)="REV-","REV-"&VALUE(MID(K55,5,99)),IF(LEN(K55)=5,LEFT(K55,2)&"."&RIGHT(K55,3),K55)),verfvoorraad!E:E,verfvoorraad!E:E),"Niet gevonden"))) | O55: =IF(K55="","",IFERROR(_xlfn.XLOOKUP(K55,verfvoorraad!C:C,verfvoorraad!F:F),IFERROR(_xlfn.XLOOKUP(IF(LEFT(UPPER(K55),4)="REV-","REV-"&VALUE(MID(K55,5,99)),IF(LEN(K55)=5,LEFT(K55,2)&"."&RIGHT(K55,3),K55)),verfvoorraad!E:E,verfvoorraad!F:F),"Niet gevonden"))) | P55: =IF(K55="","",IFERROR(_xlfn.XLOOKUP(K55,verfvoorraad!C:C,verfvoorraad!G:G),IFERROR(_xlfn.XLOOKUP(IF(LEFT(UPPER(K55),4)="REV-","REV-"&VALUE(MID(K55,5,99)),IF(LEN(K55)=5,LEFT(K55,2)&"."&RIGHT(K55,3),K55)),verfvoorraad!E:E,verfvoorraad!G:G),"Niet gevonden"))) | Q55: =IF(K55="","",IF(O55="Ja","Nee",IF(O55="Nee","Ja",IF(O55="Niet gevonden","Niet gevonden","")))) | R55: =IF(Q55="Ja","Toevoegen","")
...

Sheet Bestellijst
B5: Bestellijst Valleyo verf:
B7: Kleurnaam: | C7: Artikelnummer: | D7: Reeks: | E7: Volledig nummer: | F7: in voorraad: | G7: Aantal bestellen: | H7: Totaal kleuren: | I7: Totaal potjes:
B8: {=IFERROR(_xlfn._xlws.SORT(_xlfn._xlws.FILTER(CHOOSE({1,2,3,4,5,6},verfvoorraad!B8:B505,verfvoorraad!C8:C505,verfvoorraad!D8:D505,verfvoorraad!E8:E505,verfvoorraad!F8:F505,verfvoorraad!I8:I505),verfvoorraad!H8:H505="Ja"),3,1),"Geen verf om te bestellen")} -> Model Air - Rust | C8: 080 | D8: Model Air | E8: 71.080 | F8: Nee | G8: 1 | H8: =COUNTIF(verfvoorraad!H8:H505,"Ja") -> 1 | I8: =SUM(G8:G505) -> 1

Sheet Table
B5: In voorraad:
B6: Nee
B7: Ja
